Workbook

Sheet H2O Calculations
G2: Power Law Formulations | O2: Unified Mixing Rule | AA2: Virial Based Mixing Rule
G3: Silberstein Formula Linear Law | I3: Birchak Formula Square Root Law | K3: Looyenga Formula Cubic Root Law | M3: Generalized Power Law | O3: Maxwell Garnett Rule | Q3: Polder-van Santen Formula | S3: Coherent Potential Approximation | U3: Generalized Unified Mixing Rule
G4: (β=1) | I4: (β=1/2) | K4: (β=1/3) | M4: 0.33 | O4: (ν=0) | Q4: (ν=2) | S4: (ν=3) | Y4: 0 | AB4: =($E$40/($E$60*$E$43)) -> 40.873998
A7: RH [%] | C7: rmol [ppm] | D7: XH2O [mol/mol] | E7: XAir [mol/mol] | G7: εr [1] | I7: εr [2] | K7: εr [3] | M7: εr [4] | O7: Column1 | Q7: Column1 | S7: Column1 | U7: a | V7: b | W7: c | X7: x | Y7: εr [5] | AA7: BMIX | AB7: ρMIX | AC7: Πmix | AD7: εr [6] | AF7: Πmix | AG7: εr [6]
A8: 0 | C8: =1000000*(A8/100)*$E$45/$E$41 -> 0 | D8: =C8/10000 -> 0 | E8: =1-D8 -> 1 | G8: =E8*$E$57+D8*$E$46 -> 1.0005378 | I8: =(E8*$E$57^(1/2)+D8*$E$46^(1/2))^2 -> 1.0005378 | K8: =(E8*$E$57^(1/3)+D8*$E$46^(1/3))^3 -> 1.0005378 | M8: =(E8*$E$57^($M$4)+D8*$E$46^($M$4))^(1/$M$4) -> 1.0005378 | O8: =$E$57+3*D8*$E$57*(($E$46-$E$57)/($E$46+2*$E$57-D8*($E$46-$E$57))) -> 1.0005378 | U8: =$Y$4 -> 0 | V8: =$E$46*(1-D8*(1+$Y$4))+$E$57*(2+D8*(1+$Y$4)) -> 80.304419 | W8: =-($E$46-$E$57)*D8*3*$E$57 -> 0 | X8: =IF(U8=0,-W8/V8,(-V8+SQRT(V8^2-4*U8*W8))/2*U8) -> 0 | Y8: =X8+$E$57 -> 1.0005378 | AA8: =E8^2*$AB$48+2*E8*D8*$AB$50+D8^2*$AB$49 -> -7.6244426e-06 | AB8: =$E$40/(($E$60*$E$43)*(1+(AA9*$E$40/($E$60*$E$43)))) -> 40.886743 | AC8: =$E$56*E8+$E$47*D8 -> 4.3850492 | AD8: =(2*(AB8)*AC8*0.000001+1)/(1-(AB8)*AC8*0.000001) -> 1.000538 | AF8: =$E$56*E8+$E$47*D8 -> 4.3850492 | AG8: =(2*($E$40/($E$60*$E$43))*AF8*0.000001+1)/(1-($E$40/($E$60*$E$43))*AF8*0.000001) -> 1.0005378
A9: 0.1 | C9: =1000000*(A9/100)*$E$45/$E$41 -> 31.270974 | D9: =C9/1000000 -> 3.1270974e-05 | E9: =1-D9 -> 0.99996873 | G9: =E9*$E$57+D9*$E$46 -> 1.0029551 | I9: =(E9*$E$57^(1/2)+D9*$E$46^(1/2))^2 -> 1.0010289 | K9: =(E9*$E$57^(1/3)+D9*$E$46^(1/3))^3 -> 1.0008455 | M9: =(E9*$E$57^($M$4)+D9*$E$46^($M$4))^(1/$M$4) -> 1.0008427 | O9: =$E$57+3*D9*$E$57*(($E$46-$E$57)/($E$46+2*$E$57-D9*($E$46-$E$57))) -> 1.0006282 | U9: =$Y$4 -> 0 | V9: =$E$46*(1-D9*(1+$Y$4))+$E$57*(2+D9*(1+$Y$4)) -> 80.302002 | W9: =-($E$46-$E$57)*D9*3*$E$57 -> -0.0072559022 | X9: =IF(U9=0,-W9/V9,(-V9+SQRT(V9^2-4*U9*W9))/2*U9) -> 9.0357675e-05 | Y9: =X9+$E$57 -> 1.0006282 | AA9: =E9^2*$AB$48+2*E9*D9*$AB$50+D9^2*$AB$49 -> -7.6257963e-06 | AB9: =$E$40/(($E$60*$E$43)*(1+(AA10*$E$40/($E$60*$E$43)))) -> 40.886745 | AC9: =$E$56*E9+$E$47*D9 -> 5.1213887 | AD9: =(2*(AB9)*AC9*0.000001+1)/(1-(AB9)*AC9*0.000001) -> 1.0006283 | AF9: =$E$56*E9+$E$47*D9 -> 5.1213887 | AG9: =(2*($E$40/($E$60*$E$43))*AF9*0.000001+1)/(1-($E$40/($E$60*$E$43))*AF9*0.000001) -> 1.0006281
A10: 0.2 | C10: =1000000*(A10/100)*$E$45/$E$41 -> 62.541947 | D10: =C10/1000000 -> 6.2541947e-05 | E10: =1-D10 -> 0.99993746 | G10: =E10*$E$57+D10*$E$46 -> 1.0053725 | I10: =(E10*$E$57^(1/2)+D10*$E$46^(1/2))^2 -> 1.00152 | K10: =(E10*$E$57^(1/3)+D10*$E$46^(1/3))^3 -> 1.0011532 | M10: =(E10*$E$57^($M$4)+D10*$E$46^($M$4))^(1/$M$4) -> 1.0011477 | O10: =$E$57+3*D10*$E$57*(($E$46-$E$57)/($E$46+2*$E$57-D10*($E$46-$E$57))) -> 1.0007185 | U10: =$Y$4 -> 0 | V10: =$E$46*(1-D10*(1+$Y$4))+$E$57*(2+D10*(1+$Y$4)) -> 80.299585 | W10: =-($E$46-$E$57)*D10*3*$E$57 -> -0.014511804 | X10: =IF(U10=0,-W10/V10,(-V10+SQRT(V10^2-4*U10*W10))/2*U10) -> 0.00018072079 | Y10: =X10+$E$57 -> 1.0007185 | AA10: =E10^2*$AB$48+2*E10*D10*$AB$50+D10^2*$AB$49 -> -7.6271498e-06 | AB10: =$E$40/(($E$60*$E$43)*(1+(AA11*$E$40/($E$60*$E$43)))) -> 40.886747 | AC10: =$E$56*E10+$E$47*D10 -> 5.8577281 | AD10: =(2*(AB10)*AC10*0.000001+1)/(1-(AB10)*AC10*0.000001) -> 1.0007187 | AF10: =$E$56*E10+$E$47*D10 -> 5.8577281 | AG10: =(2*($E$40/($E$60*$E$43))*AF10*0.000001+1)/(1-($E$40/($E$60*$E$43))*AF10*0.000001) -> 1.0007185
A11: 0.3 | C11: =1000000*(A11/100)*$E$45/$E$41 -> 93.812921 | D11: =C11/1000000 -> 9.3812921e-05 | E11: =1-D11 -> 0.99990619 | G11: =E11*$E$57+D11*$E$46 -> 1.0077898 | I11: =(E11*$E$57^(1/2)+D11*$E$46^(1/2))^2 -> 1.0020113 | K11: =(E11*$E$57^(1/3)+D11*$E$46^(1/3))^3 -> 1.001461 | M11: =(E11*$E$57^($M$4)+D11*$E$46^($M$4))^(1/$M$4) -> 1.0014527 | O11: =$E$57+3*D11*$E$57*(($E$46-$E$57)/($E$46+2*$E$57-D11*($E$46-$E$57))) -> 1.0008089 | U11: =$Y$4 -> 0 | V11: =$E$46*(1-D11*(1+$Y$4))+$E$57*(2+D11*(1+$Y$4)) -> 80.297167 | W11: =-($E$46-$E$57)*D11*3*$E$57 -> -0.021767706 | X11: =IF(U11=0,-W11/V11,(-V11+SQRT(V11^2-4*U11*W11))/2*U11) -> 0.00027108934 | Y11: =X11+$E$57 -> 1.0008089 | AA11: =E11^2*$AB$48+2*E11*D11*$AB$50+D11^2*$AB$49 -> -7.6285033e-06 | AB11: =$E$40/(($E$60*$E$43)*(1+(AA12*$E$40/($E$60*$E$43)))) -> 40.886749 | AC11: =$E$56*E11+$E$47*D11 -> 6.5940676 | AD11: =(2*(AB11)*AC11*0.000001+1)/(1-(AB11)*AC11*0.000001) -> 1.000809 | AF11: =$E$56*E11+$E$47*D11 -> 6.5940676 | AG11: =(2*($E$40/($E$60*$E$43))*AF11*0.000001+1)/(1-($E$40/($E$60*$E$43))*AF11*0.000001) -> 1.0008088
A12: 0.4 | C12: =1000000*(A12/100)*$E$45/$E$41 -> 125.08389 | D12: =C12/1000000 -> 0.00012508389 | E12: =1-D12 -> 0.99987492 | G12: =E12*$E$57+D12*$E$46 -> 1.0102071 | I12: =(E12*$E$57^(1/2)+D12*$E$46^(1/2))^2 -> 1.0025028 | K12: =(E12*$E$57^(1/3)+D12*$E$46^(1/3))^3 -> 1.0017688 | M12: =(E12*$E$57^($M$4)+D12*$E$46^($M$4))^(1/$M$4) -> 1.0017578 | O12: =$E$57+3*D12*$E$57*(($E$46-$E$57)/($E$46+2*$E$57-D12*($E$46-$E$57))) -> 1.0008993 | U12: =$Y$4 -> 0 | V12: =$E$46*(1-D12*(1+$Y$4))+$E$57*(2+D12*(1+$Y$4)) -> 80.29475 | W12: =-($E$46-$E$57)*D12*3*$E$57 -> -0.029023609 | X12: =IF(U12=0,-W12/V12,(-V12+SQRT(V12^2-4*U12*W12))/2*U12) -> 0.00036146334 | Y12: =X12+$E$57 -> 1.0008993 | AA12: =E12^2*$AB$48+2*E12*D12*$AB$50+D12^2*$AB$49 -> -7.6298567e-06 | AB12: =$E$40/(($E$60*$E$43)*(1+(AA13*$E$40/($E$60*$E$43)))) -> 40.886752 | AC12: =$E$56*E12+$E$47*D12 -> 7.330407 | AD12: =(2*(AB12)*AC12*0.000001+1)/(1-(AB12)*AC12*0.000001) -> 1.0008994 | AF12: =$E$56*E12+$E$47*D12 -> 7.330407 | AG12: =(2*($E$40/($E$60*$E$43))*AF12*0.000001+1)/(1-($E$40/($E$60*$E$43))*AF12*0.000001) -> 1.0008991
A13: 0.5 | C13: =1000000*(A13/100)*$E$45/$E$41 -> 156.35487 | D13: =C13/1000000 -> 0.00015635487 | E13: =1-D13 -> 0.99984365 | G13: =E13*$E$57+D13*$E$46 -> 1.0126245 | I13: =(E13*$E$57^(1/2)+D13*$E$46^(1/2))^2 -> 1.0029943 | K13: =(E13*$E$57^(1/3)+D13*$E$46^(1/3))^3 -> 1.0020767 | M13: =(E13*$E$57^($M$4)+D13*$E$46^($M$4))^(1/$M$4) -> 1.002063 | O13: =$E$57+3*D13*$E$57*(($E$46-$E$57)/($E$46+2*$E$57-D13*($E$46-$E$57))) -> 1.0009896 | U13: =$Y$4 -> 0 | V13: =$E$46*(1-D13*(1+$Y$4))+$E$57*(2+D13*(1+$Y$4)) -> 80.292333 | W13: =-($E$46-$E$57)*D13*3*$E$57 -> -0.036279511 | X13: =IF(U13=0,-W13/V13,(-V13+SQRT(V13^2-4*U13*W13))/2*U13) -> 0.00045184278 | Y13: =X13+$E$57 -> 1.0009896 | AA13: =E13^2*$AB$48+2*E13*D13*$AB$50+D13^2*$AB$49 -> -7.6312099e-06 | AB13: =$E$40/(($E$60*$E$43)*(1+(AA14*$E$40/($E$60*$E$43)))) -> 40.886754 | AC13: =$E$56*E13+$E$47*D13 -> 8.0667464 | AD13: =(2*(AB13)*AC13*0.000001+1)/(1-(AB13)*AC13*0.000001) -> 1.0009898 | AF13: =$E$56*E13+$E$47*D13 -> 8.0667464 | AG13: =(2*($E$40/($E$60*$E$43))*AF13*0.000001+1)/(1-($E$40/($E$60*$E$43))*AF13*0.000001) -> 1.0009895
A14: 0.6 | C14: =1000000*(A14/100)*$E$45/$E$41 -> 187.62584 | D14: =C14/1000000 -> 0.00018762584 | E14: =1-D14 -> 0.99981237 | G14: =E14*$E$57+D14*$E$46 -> 1.0150418 | I14: =(E14*$E$57^(1/2)+D14*$E$46^(1/2))^2 -> 1.003486 | K14: =(E14*$E$57^(1/3)+D14*$E$46^(1/3))^3 -> 1.0023847 | M14: =(E14*$E$57^($M$4)+D14*$E$46^($M$4))^(1/$M$4) -> 1.0023682 | O14: =$E$57+3*D14*$E$57*(($E$46-$E$57)/($E$46+2*$E$57-D14*($E$46-$E$57))) -> 1.00108 | U14: =$Y$4 -> 0 | V14: =$E$46*(1-D14*(1+$Y$4))+$E$57*(2+D14*(1+$Y$4)) -> 80.289915 | W14: =-($E$46-$E$57)*D14*3*$E$57 -> -0.043535413 | X14: =IF(U14=0,-W14/V14,(-V14+SQRT(V14^2-4*U14*W14))/2*U14) -> 0.00054222766 | Y14: =X14+$E$57 -> 1.00108 | AA14: =E14^2*$AB$48+2*E14*D14*$AB$50+D14^2*$AB$49 -> -7.6325631e-06 | AB14: =$E$40/(($E$60*$E$43)*(1+(AA15*$E$40/($E$60*$E$43)))) -> 40.886756 | AC14: =$E$56*E14+$E$47*D14 -> 8.8030859 | AD14: =(2*(AB14)*AC14*0.000001+1)/(1-(AB14)*AC14*0.000001) -> 1.0010802 | AF14: =$E$56*E14+$E$47*D14 -> 8.8030859 | AG14: =(2*($E$40/($E$60*$E$43))*AF14*0.000001+1)/(1-($E$40/($E$60*$E$43))*AF14*0.000001) -> 1.0010798
A15: 0.7 | C15: =1000000*(A15/100)*$E$45/$E$41 -> 218.89682 | D15: =C15/1000000 -> 0.00021889682 | E15: =1-D15 -> 0.9997811 | G15: =E15*$E$57+D15*$E$46 -> 1.0174591 | I15: =(E15*$E$57^(1/2)+D15*$E$46^(1/2))^2 -> 1.0039778 | K15: =(E15*$E$57^(1/3)+D15*$E$46^(1/3))^3 -> 1.0026928 | M15: =(E15*$E$57^($M$4)+D15*$E$46^($M$4))^(1/$M$4) -> 1.0026735 | O15: =$E$57+3*D15*$E$57*(($E$46-$E$57)/($E$46+2*$E$57-D15*($E$46-$E$57))) -> 1.0011704 | U15: =$Y$4 -> 0 | V15: =$E$46*(1-D15*(1+$Y$4))+$E$57*(2+D15*(1+$Y$4)) -> 80.287498 | W15: =-($E$46-$E$57)*D15*3*$E$57 -> -0.050791315 | X15: =IF(U15=0,-W15/V15,(-V15+SQRT(V15^2-4*U15*W15))/2*U15) -> 0.00063261798 | Y15: =X15+$E$57 -> 1.0011704 | AA15: =E15^2*$AB$48+2*E15*D15*$AB$50+D15^2*$AB$49 -> -7.6339162e-06 | AB15: =$E$40/(($E$60*$E$43)*(1+(AA16*$E$40/($E$60*$E$43)))) -> 40.886759 | AC15: =$E$56*E15+$E$47*D15 -> 9.5394253 | AD15: =(2*(AB15)*AC15*0.000001+1)/(1-(AB15)*AC15*0.000001) -> 1.0011706 | AF15: =$E$56*E15+$E$47*D15 -> 9.5394253 | AG15: =(2*($E$40/($E$60*$E$43))*AF15*0.000001+1)/(1-($E$40/($E$60*$E$43))*AF15*0.000001) -> 1.0011702
A16: 0.8 | C16: =1000000*(A16/100)*$E$45/$E$41 -> 250.16779 | D16: =C16/1000000 -> 0.00025016779 | E16: =1-D16 -> 0.99974983 | G16: =E16*$E$57+D16*$E$46 -> 1.0198765 | I16: =(E16*$E$57^(1/2)+D16*$E$46^(1/2))^2 -> 1.0044697 | K16: =(E16*$E$57^(1/3)+D16*$E$46^(1/3))^3 -> 1.0030009 | M16: =(E16*$E$57^($M$4)+D16*$E$46^($M$4))^(1/$M$4) -> 1.0029789 | O16: =$E$57+3*D16*$E$57*(($E$46-$E$57)/($E$46+2*$E$57-D16*($E$46-$E$57))) -> 1.0012608 | U16: =$Y$4 -> 0 | V16: =$E$46*(1-D16*(1+$Y$4))+$E$57*(2+D16*(1+$Y$4)) -> 80.285081 | W16: =-($E$46-$E$57)*D16*3*$E$57 -> -0.058047217 | X16: =IF(U16=0,-W16/V16,(-V16+SQRT(V16^2-4*U16*W16))/2*U16) -> 0.00072301375 | Y16: =X16+$E$57 -> 1.0012608 | AA16: =E16^2*$AB$48+2*E16*D16*$AB$50+D16^2*$AB$49 -> -7.6352691e-06 | AB16: =$E$40/(($E$60*$E$43)*(1+(AA17*$E$40/($E$60*$E$43)))) -> 40.886761 | AC16: =$E$56*E16+$E$47*D16 -> 10.275765 | AD16: =(2*(AB16)*AC16*0.000001+1)/(1-(AB16)*AC16*0.000001) -> 1.001261 | AF16: =$E$56*E16+$E$47*D16 -> 10.275765 | AG16: =(2*($E$40/($E$60*$E$43))*AF16*0.000001+1)/(1-($E$40/($E$60*$E$43))*AF16*0.000001) -> 1.0012606
A17: 0.9 | C17: =1000000*(A17/100)*$E$45/$E$41 -> 281.43876 | D17: =C17/1000000 -> 0.00028143876 | E17: =1-D17 -> 0.99971856 | G17: =E17*$E$57+D17*$E$46 -> 1.0222938 | I17: =(E17*$E$57^(1/2)+D17*$E$46^(1/2))^2 -> 1.0049617 | K17: =(E17*$E$57^(1/3)+D17*$E$46^(1/3))^3 -> 1.003309 | M17: =(E17*$E$57^($M$4)+D17*$E$46^($M$4))^(1/$M$4) -> 1.0032843 | O17: =$E$57+3*D17*$E$57*(($E$46-$E$57)/($E$46+2*$E$57-D17*($E$46-$E$57))) -> 1.0013512 | U17: =$Y$4 -> 0 | V17: =$E$46*(1-D17*(1+$Y$4))+$E$57*(2+D17*(1+$Y$4)) -> 80.282663 | W17: =-($E$46-$E$57)*D17*3*$E$57 -> -0.065303119 | X17: =IF(U17=0,-W17/V17,(-V17+SQRT(V17^2-4*U17*W17))/2*U17) -> 0.00081341496 | Y17: =X17+$E$57 -> 1.0013512 | AA17: =E17^2*$AB$48+2*E17*D17*$AB$50+D17^2*$AB$49 -> -7.636622e-06 | AB17: =$E$40/(($E$60*$E$43)*(1+(AA18*$E$40/($E$60*$E$43)))) -> 40.886763 | AC17: =$E$56*E17+$E$47*D17 -> 11.012104 | AD17: =(2*(AB17)*AC17*0.000001+1)/(1-(AB17)*AC17*0.000001) -> 1.0013514 | AF17: =$E$56*E17+$E$47*D17 -> 11.012104 | AG17: =(2*($E$40/($E$60*$E$43))*AF17*0.000001+1)/(1-($E$40/($E$60*$E$43))*AF17*0.000001) -> 1.0013509
A18: 1 | C18: =1000000*(A18/100)*$E$45/$E$41 -> 312.70974 | D18: =C18/1000000 -> 0.00031270974 | E18: =1-D18 -> 0.99968729 | G18: =E18*$E$57+D18*$E$46 -> 1.0247111 | I18: =(E18*$E$57^(1/2)+D18*$E$46^(1/2))^2 -> 1.0054538 | K18: =(E18*$E$57^(1/3)+D18*$E$46^(1/3))^3 -> 1.0036173 | M18: =(E18*$E$57^($M$4)+D18*$E$46^($M$4))^(1/$M$4) -> 1.0035898 | O18: =$E$57+3*D18*$E$57*(($E$46-$E$57)/($E$46+2*$E$57-D18*($E$46-$E$57))) -> 1.0014416 | U18: =$Y$4 -> 0 | V18: =$E$46*(1-D18*(1+$Y$4))+$E$57*(2+D18*(1+$Y$4)) -> 80.280246 | W18: =-($E$46-$E$57)*D18*3*$E$57 -> -0.072559022 | X18: =IF(U18=0,-W18/V18,(-V18+SQRT(V18^2-4*U18*W18))/2*U18) -> 0.00090382162 | Y18: =X18+$E$57 -> 1.0014416 | AA18: =E18^2*$AB$48+2*E18*D18*$AB$50+D18^2*$AB$49 -> -7.6379748e-06 | AB18: =$E$40/(($E$60*$E$43)*(1+(AA19*$E$40/($E$60*$E$43)))) -> 40.886786 | AC18: =$E$56*E18+$E$47*D18 -> 11.748444 | AD18: =(2*(AB18)*AC18*0.000001+1)/(1-(AB18)*AC18*0.000001) -> 1.0014418 | AF18: =$E$56*E18+$E$47*D18 -> 11.748444 | AG18: =(2*($E$40/($E$60*$E$43))*AF18*0.000001+1)/(1-($E$40/($E$60*$E$43))*AF18*0.000001) -> 1.0014413
A19: 2 | C19: =1000000*(A19/100)*$E$45/$E$41 -> 625.41947 | D19: =C19/1000000 -> 0.00062541947 | E19: =1-D19 -> 0.99937458 | G19: =E19*$E$57+D19*$E$46 -> 1.0488845 | I19: =(E19*$E$57^(1/2)+D19*$E$46^(1/2))^2 -> 1.0103819 | K19: =(E19*$E$57^(1/3)+D19*$E$46^(1/3))^3 -> 1.006703 | M19: =(E19*$E$57^($M$4)+D19*$E$46^($M$4))^(1/$M$4) -> 1.006648 | O19: =$E$57+3*D19*$E$57*(($E$46-$E$57)/($E$46+2*$E$57-D19*($E$46-$E$57))) -> 1.002346 | U19: =$Y$4 -> 0 | V19: =$E$46*(1-D19*(1+$Y$4))+$E$57*(2+D19*(1+$Y$4)) -> 80.256073 | W19: =-($E$46-$E$57)*D19*3*$E$57 -> -0.14511804 | X19: =IF(U19=0,-W19/V19,(-V19+SQRT(V19^2-4*U19*W19))/2*U19) -> 0.0018081877 | Y19: =X19+$E$57 -> 1.002346 | AA19: =E19^2*$AB$48+2*E19*D19*$AB$50+D19^2*$AB$49 -> -7.651497e-06 | AB19: =$E$40/(($E$60*$E$43)*(1+(AA20*$E$40/($E$60*$E$43)))) -> 40.886808 | AC19: =$E$56*E19+$E$47*D19 -> 19.111838 | AD19: =(2*(AB19)*AC19*0.000001+1)/(1-(AB19)*AC19*0.000001) -> 1.0023461 | AF19: =$E$56*E19+$E$47*D19 -> 19.111838 | AG19: =(2*($E$40/($E$60*$E$43))*AF19*0.000001+1)/(1-($E$40/($E$60*$E$43))*AF19*0.000001) -> 1.0023454
A20: 3 | C20: =1000000*(A20/100)*$E$45/$E$41 -> 938.12921 | D20: =C20/1000000 -> 0.00093812921 | E20: =1-D20 -> 0.99906187 | G20: =E20*$E$57+D20*$E$46 -> 1.0730578 | I20: =(E20*$E$57^(1/2)+D20*$E$46^(1/2))^2 -> 1.0153221 | K20: =(E20*$E$57^(1/3)+D20*$E$46^(1/3))^3 -> 1.0097951 | M20: =(E20*$E$57^($M$4)+D20*$E$46^($M$4))^(1/$M$4) -> 1.0097124 | O20: =$E$57+3*D20*$E$57*(($E$46-$E$57)/($E$46+2*$E$57-D20*($E$46-$E$57))) -> 1.0032509 | U20: =$Y$4 -> 0 | V20: =$E$46*(1-D20*(1+$Y$4))+$E$57*(2+D20*(1+$Y$4)) -> 80.231899 | W20: =-($E$46-$E$57)*D20*3*$E$57 -> -0.21767706 | X20: =IF(U20=0,-W20/V20,(-V20+SQRT(V20^2-4*U20*W20))/2*U20) -> 0.0027130987 | Y20: =X20+$E$57 -> 1.0032509 | AA20: =E20^2*$AB$48+2*E20*D20*$AB$50+D20^2*$AB$49 -> -7.6650093e-06 | AB20: =$E$40/(($E$60*$E$43)*(1+(AA21*$E$40/($E$60*$E$43)))) -> 40.886831 | AC20: =$E$56*E20+$E$47*D20 -> 26.475232 | AD20: =(2*(AB20)*AC20*0.000001+1)/(1-(AB20)*AC20*0.000001) -> 1.003251 | AF20: =$E$56*E20+$E$47*D20 -> 26.475232 | AG20: =(2*($E$40/($E$60*$E$43))*AF20*0.000001+1)/(1-($E$40/($E$60*$E$43))*AF20*0.000001) -> 1.00325
... A36: 100 | C36: =1000000*(A36/100)*$E$45/$E$41 -> 31270.974 | D36: =C36/1000000 -> 0.031270974 | E36: =1-D36 -> 0.96872903 | G36: =E36*$E$57+D36*$E$46 -> 3.4178718 | I36: =(E36*$E$57^(1/2)+D36*$E$46^(1/2))^2 -> 1.5517778 | K36: =(E36*$E$57^(1/3)+D36*$E$46^(1/3))^3 -> 1.3407734 | M36: =(E36*$E$57^($M$4)+D36*$E$46^($M$4))^(1/$M$4) -> 1.3376228 | O36: =$E$57+3*D36*$E$57*(($E$46-$E$57)/($E$46+2*$E$57-D36*($E$46-$E$57))) -> 1.093697 | U36: =$Y$4 -> 0 | V36: =$E$46*(1-D36*(1+$Y$4))+$E$57*(2+D36*(1+$Y$4)) -> 77.887085 | W36: =-($E$46-$E$57)*D36*3*$E$57 -> -7.2559022 | X36: =IF(U36=0,-W36/V36,(-V36+SQRT(V36^2-4*U36*W36))/2*U36) -> 0.093159246 | Y36: =X36+$E$57 -> 1.093697 | AA36: =E36^2*$AB$48+2*E36*D36*$AB$50+D36^2*$AB$49 -> -8.9283715e-06 | AB36: =$E$40/(($E$60*$E$43)*(1+(AA37*$E$40/($E$60*$E$43)))) -> 40.873998 | AC36: =$E$56*E36+$E$47*D36 -> 740.72449 | AD36: =(2*(AB36)*AC36*0.000001+1)/(1-(AB36)*AC36*0.000001) -> 1.0936649 | AF36: =$E$56*E36+$E$47*D36 -> 740.72449 | AG36: =(2*($E$40/($E$60*$E$43))*AF36*0.000001+1)/(1-($E$40/($E$60*$E$43))*AF36*0.000001) -> 1.0936649
A39: Environment Constants | AA39: AW | AB39: 3.96 | AF39: 3.96
A40: Ambient Pressure (P) [Pa] | E40: 101325 | AA40: BW | AB40: 20770 | AF40: 20770
A41: Ambient Pressure (P) [atm] | E41: =E40/101325 -> 1 | AA41: Πw | AB41: =AB39+AB40/E43 -> 73.622921 | AC41: =3.84+2.092*10000/E43 -> 74.006024 | AF41: 73.622921
A42: Temperature (T) [°C] | E42: 25
A43: Temperature (T) [K] | E43: =E42+273.15 -> 298.15 | M43: =1000/E43 -> 3.3540164
A45: Water Vapor Pressure [atm] | E45: =0.61121*EXP(((18.678-E42/234.5)*(E42/(257.14+E42))))/101.325 -> 0.031270974
A46: Water Permittivity [NA] | E46: =87.74-0.40008*E42+9.398*0.0001*E42^2-1.41*0.000001*E42^3 -> 78.303344
A47: Water Molar Polarizability [cm³/mol] | E47: =(($E$46-1)/($E$46+2))*(($E$60*$E$43/$E$40)*1000000) -> 23551.443
AA48: BAA | AB48: =(34.9568-6687.72/(E43)-2101410/(E43^2)+92474600/(E43^3))*0.000001 -> -7.6244426e-06
A49: N2 Molecular Polarizability [Ǻ³] | E49: =(1.7037*1E-30+3.01*1E-34*E43-2*1E-37*E43^2)*1E+30 -> 1.7756645 | AA49: BWW | AB49: =E60*E43*(0.000000007-0.00000000147184*EXP(1734.29/E43))*0.000001 -> -1.2082519e-09
A50: O2 Molecular Polarizability [Ǻ³] | E50: =(1.5343*1E-30+2.88*1E-34*E43-1.63*1E-37*E43^2)*1E+30 -> 1.6056776 | AA50: BAW | AB50: =(32.366097-14113.8/(E43)-1244535/(E43^2)-2348789000/(E43^4))*0.000001 -> -2.9269363e-05
A51: Ar Molecular Polarizability [Ǻ³] | E51: =(1.62526*1E-30+1.649*1E-34*E43)*1E+30 -> 1.6744249
A52: N2 Fraction [%] | E52: 0.780818
A53: O2 Fraction [%] | E53: 0.209435
A54: Ar Fraction [%] | E54: 0.009332 | AA54: 1.501 | AB54: 1.855e-29
A55: Average Air Molecular Polarizability [Ǻ³] | E55: =E52*E49+E53*E50+E54*E51 -> 1.7383816 | AA55: =AA54/1E+24 -> 1.501e-24 | AB55: =AB54^2/(3*E62*E43) -> 2.7864322e-38
A56: Air Molar Polarizability [cm³/mol] | E56: =1E-24*4*PI()*E55*E61/3 -> 4.3850492 | Y56: =(4*PI()/3)*(E61)*(AA55+AB55) -> 3.7862567
A57: Air Permittivity | E57: =(2*(E40/(E60*E43))*E56*0.000001+1)/(1-(E40/(E60*E43)*E56*0.000001)) -> 1.0005378 | Y57: =(2*(E40/(E60*E43))*Y56*0.000001+1)/(1-(E40/(E60*E43)*Y56*0.000001)) -> 1.0004644
A59: Vacuum Permittivity (ε0) [F/m] | E59: 8.8542e-12
A60: Universal Gas Constant (R) [m3.Pa/mol.K] | E60: 8.314472
A61: Avogadro Constant (NA) [1/mol] | E61: 6.022e+23
A62: Boltzman Constant (kB) [J/K] | E62: 1.380649e-23
...

Sheet Calculo de Dk H2O
C1: MATLAB | D1: Wheller Conformal Narrow | E1: Wheller Conformal Wide | F1: Energy | G1: Sierra
D2: W/h>1 | E2: W/h<1 | H2: W/h<1 | J2: W/h>1
D3: Svacina [1992] | K3: W/h>2 | L3: W/h<2
A4: RH [%] | B4: ΕMUT | C4: εEFF | D4: εEFF2 | E4: εEFF3 | F4: εEFF4 | G4: εEFF5 | H4: Column1 | I4: Column2 | J4: Column3 | K4: Column4 | L4: Column5 | M4: Column6 | N4: Column7 | O4: Column8 | P4: Column9
A5: ='H2O Calculations'!A8 -> 0 | B5: ='H2O Calculations'!AG8 -> 1.0005378 | C5: =($C$42^2/($C$42/$C$51))+($C$44^2/($C$44/B5)) -> 3.146875 | D5: =$C$51*$D$42+B5*((1-$D$42)^2)/(B5*(1-$D$42-$D$44)+$D$44) -> 3.3558253 | E5: =$C$51*$E$42+B5*((1-$E$42)^2)/(B5*(1-$E$42-$E$44)+$E$44) -> 1.1431489 | G5: 3.29577 | H5: =$C$51*$H$42+B5*(1-$H$42)^2/(B5*(1-$H$42-$H$44)+$H$44) -> 3.3558253 | I5: =120*PI()*$B$51/($H$37*SQRT(H5)) -> 50.56202 | P5: =B5-1 -> 0.00053779988
A6: ='H2O Calculations'!A9 -> 0.1 | B6: ='H2O Calculations'!AG9 -> 1.0006281 | C6: =($C$42^2/($C$42/$C$51))+($C$44^2/($C$44/B6)) -> 3.146908 | D6: =$C$51*$D$42+B6*((1-$D$42)^2)/(B6*(1-$D$42-$D$44)+$D$44) -> 3.3558527 | E6: =$C$51*$E$42+B6*((1-$E$42)^2)/(B6*(1-$E$42-$E$44)+$E$44) -> 1.1431489 | H6: =$C$51*$H$42+B6*(1-$H$42)^2/(B6*(1-$H$42-$H$44)+$H$44) -> 3.3558527 | I6: =120*PI()*$B$51/($H$37*SQRT(H6)) -> 50.561813 | P6: =B6-1 -> 0.00062812639
A7: ='H2O Calculations'!A10 -> 0.2 | B7: ='H2O Calculations'!AG10 -> 1.0007185 | C7: =($C$42^2/($C$42/$C$51))+($C$44^2/($C$44/B7)) -> 3.1469409 | D7: =$C$51*$D$42+B7*((1-$D$42)^2)/(B7*(1-$D$42-$D$44)+$D$44) -> 3.35588 | E7: =$C$51*$E$42+B7*((1-$E$42)^2)/(B7*(1-$E$42-$E$44)+$E$44) -> 1.1431489 | H7: =$C$51*$H$42+B7*(1-$H$42)^2/(B7*(1-$H$42-$H$44)+$H$44) -> 3.35588 | I7: =120*PI()*$B$51/($H$37*SQRT(H7)) -> 50.561607 | P7: =B7-1 -> 0.00071845833
A8: ='H2O Calculations'!A11 -> 0.3 | B8: ='H2O Calculations'!AG11 -> 1.0008088 | C8: =($C$42^2/($C$42/$C$51))+($C$44^2/($C$44/B8)) -> 3.1469739 | D8: =$C$51*$D$42+B8*((1-$D$42)^2)/(B8*(1-$D$42-$D$44)+$D$44) -> 3.3559074 | E8: =$C$51*$E$42+B8*((1-$E$42)^2)/(B8*(1-$E$42-$E$44)+$E$44) -> 1.1431489 | H8: =$C$51*$H$42+B8*(1-$H$42)^2/(B8*(1-$H$42-$H$44)+$H$44) -> 3.3559074 | I8: =120*PI()*$B$51/($H$37*SQRT(H8)) -> 50.561401 | P8: =B8-1 -> 0.00080879571
A9: ='H2O Calculations'!A12 -> 0.4 | B9: ='H2O Calculations'!AG12 -> 1.0008991 | C9: =($C$42^2/($C$42/$C$51))+($C$44^2/($C$44/B9)) -> 3.1470069 | D9: =$C$51*$D$42+B9*((1-$D$42)^2)/(B9*(1-$D$42-$D$44)+$D$44) -> 3.3559348 | E9: =$C$51*$E$42+B9*((1-$E$42)^2)/(B9*(1-$E$42-$E$44)+$E$44) -> 1.1431489 | H9: =$C$51*$H$42+B9*(1-$H$42)^2/(B9*(1-$H$42-$H$44)+$H$44) -> 3.3559348 | I9: =120*PI()*$B$51/($H$37*SQRT(H9)) -> 50.561195 | P9: =B9-1 -> 0.00089913854
A10: ='H2O Calculations'!A13 -> 0.5 | B10: ='H2O Calculations'!AG13 -> 1.0009895 | C10: =($C$42^2/($C$42/$C$51))+($C$44^2/($C$44/B10)) -> 3.1470398 | D10: =$C$51*$D$42+B10*((1-$D$42)^2)/(B10*(1-$D$42-$D$44)+$D$44) -> 3.3559622 | E10: =$C$51*$E$42+B10*((1-$E$42)^2)/(B10*(1-$E$42-$E$44)+$E$44) -> 1.1431489 | H10: =$C$51*$H$42+B10*(1-$H$42)^2/(B10*(1-$H$42-$H$44)+$H$44) -> 3.3559622 | I10: =120*PI()*$B$51/($H$37*SQRT(H10)) -> 50.560988 | P10: =B10-1 -> 0.0009894868
A11: ='H2O Calculations'!A14 -> 0.6 | B11: ='H2O Calculations'!AG14 -> 1.0010798 | C11: =($C$42^2/($C$42/$C$51))+($C$44^2/($C$44/B11)) -> 3.1470728 | D11: =$C$51*$D$42+B11*((1-$D$42)^2)/(B11*(1-$D$42-$D$44)+$D$44) -> 3.3559895 | E11: =$C$51*$E$42+B11*((1-$E$42)^2)/(B11*(1-$E$42-$E$44)+$E$44) -> 1.1431489 | H11: =$C$51*$H$42+B11*(1-$H$42)^2/(B11*(1-$H$42-$H$44)+$H$44) -> 3.3559895 | I11: =120*PI()*$B$51/($H$37*SQRT(H11)) -> 50.560782 | P11: =B11-1 -> 0.0010798405
A12: ='H2O Calculations'!A15 -> 0.7 | B12: ='H2O Calculations'!AG15 -> 1.0011702 | C12: =($C$42^2/($C$42/$C$51))+($C$44^2/($C$44/B12)) -> 3.1471058 | D12: =$C$51*$D$42+B12*((1-$D$42)^2)/(B12*(1-$D$42-$D$44)+$D$44) -> 3.3560169 | E12: =$C$51*$E$42+B12*((1-$E$42)^2)/(B12*(1-$E$42-$E$44)+$E$44) -> 1.1431489 | H12: =$C$51*$H$42+B12*(1-$H$42)^2/(B12*(1-$H$42-$H$44)+$H$44) -> 3.3560169 | I12: =120*PI()*$B$51/($H$37*SQRT(H12)) -> 50.560576 | P12: =B12-1 -> 0.0011701996
A13: ='H2O Calculations'!A16 -> 0.8 | B13: ='H2O Calculations'!AG16 -> 1.0012606 | C13: =($C$42^2/($C$42/$C$51))+($C$44^2/($C$44/B13)) -> 3.1471388 | D13: =$C$51*$D$42+B13*((1-$D$42)^2)/(B13*(1-$D$42-$D$44)+$D$44) -> 3.3560443 | E13: =$C$51*$E$42+B13*((1-$E$42)^2)/(B13*(1-$E$42-$E$44)+$E$44) -> 1.1431489 | H13: =$C$51*$H$42+B13*(1-$H$42)^2/(B13*(1-$H$42-$H$44)+$H$44) -> 3.3560443 | I13: =120*PI()*$B$51/($H$37*SQRT(H13)) -> 50.56037 | P13: =B13-1 -> 0.0012605642
A14: ='H2O Calculations'!A17 -> 0.9 | B14: ='H2O Calculations'!AG17 -> 1.0013509 | C14: =($C$42^2/($C$42/$C$51))+($C$44^2/($C$44/B14)) -> 3.1471717 | D14: =$C$51*$D$42+B14*((1-$D$42)^2)/(B14*(1-$D$42-$D$44)+$D$44) -> 3.3560717 | E14: =$C$51*$E$42+B14*((1-$E$42)^2)/(B14*(1-$E$42-$E$44)+$E$44) -> 1.1431489 | H14: =$C$51*$H$42+B14*(1-$H$42)^2/(B14*(1-$H$42-$H$44)+$H$44) -> 3.3560717 | I14: =120*PI()*$B$51/($H$37*SQRT(H14)) -> 50.560163 | P14: =B14-1 -> 0.0013509343
A15: ='H2O Calculations'!A18 -> 1 | B15: ='H2O Calculations'!AG18 -> 1.0014413 | C15: =($C$42^2/($C$42/$C$51))+($C$44^2/($C$44/B15)) -> 3.1472047 | D15: =$C$51*$D$42+B15*((1-$D$42)^2)/(B15*(1-$D$42-$D$44)+$D$44) -> 3.3560991 | E15: =$C$51*$E$42+B15*((1-$E$42)^2)/(B15*(1-$E$42-$E$44)+$E$44) -> 1.1431489 | H15: =$C$51*$H$42+B15*(1-$H$42)^2/(B15*(1-$H$42-$H$44)+$H$44) -> 3.3560991 | I15: =120*PI()*$B$51/($H$37*SQRT(H15)) -> 50.559957 | P15: =B15-1 -> 0.0014413097
A16: ='H2O Calculations'!A19 -> 2 | B16: ='H2O Calculations'!AG19 -> 1.0023454 | C16: =($C$42^2/($C$42/$C$51))+($C$44^2/($C$44/B16)) -> 3.1475346 | D16: =$C$51*$D$42+B16*((1-$D$42)^2)/(B16*(1-$D$42-$D$44)+$D$44) -> 3.3563731 | E16: =$C$51*$E$42+B16*((1-$E$42)^2)/(B16*(1-$E$42-$E$44)+$E$44) -> 1.1431489 | H16: =$C$51*$H$42+B16*(1-$H$42)^2/(B16*(1-$H$42-$H$44)+$H$44) -> 3.3563731 | I16: =120*PI()*$B$51/($H$37*SQRT(H16)) -> 50.557893 | P16: =B16-1 -> 0.0023453639
A17: ='H2O Calculations'!A20 -> 3 | B17: ='H2O Calculations'!AG20 -> 1.00325 | C17: =($C$42^2/($C$42/$C$51))+($C$44^2/($C$44/B17)) -> 3.1478647 | D17: =$C$51*$D$42+B17*((1-$D$42)^2)/(B17*(1-$D$42-$D$44)+$D$44) -> 3.3566472 | E17: =$C$51*$E$42+B17*((1-$E$42)^2)/(B17*(1-$E$42-$E$44)+$E$44) -> 1.1431489 | H17: =$C$51*$H$42+B17*(1-$H$42)^2/(B17*(1-$H$42-$H$44)+$H$44) -> 3.3566472 | I17: =120*PI()*$B$51/($H$37*SQRT(H17)) -> 50.555829 | P17: =B17-1 -> 0.0032499628
... A33: ='H2O Calculations'!A36 -> 100 | B33: ='H2O Calculations'!AG36 -> 1.0936649 | C33: =($C$42^2/($C$42/$C$51))+($C$44^2/($C$44/B33)) -> 3.180856 | D33: =$C$51*$D$42+B33*((1-$D$42)^2)/(B33*(1-$D$42-$D$44)+$D$44) -> 3.3840482 | E33: =$C$51*$E$42+B33*((1-$E$42)^2)/(B33*(1-$E$42-$E$44)+$E$44) -> 1.143149 | H33: =$C$51*$H$42+B33*(1-$H$42)^2/(B33*(1-$H$42-$H$44)+$H$44) -> 3.3840482 | I33: =120*PI()*$B$51/($H$37*SQRT(H33)) -> 50.350734 | P33: =B33-1 -> 0.09366495
A34: test | B34: 4.38 | C34: =($C$42^2/($C$42/$C$51))+($C$44^2/($C$44/B34)) -> 4.38 | D34: =$C$51*$D$42+B34*((1-$D$42)^2)/(B34*(1-$D$42-$D$44)+$D$44) -> 4.38 | E34: =$C$51*$E$42+B34*((1-$E$42)^2)/(B34*(1-$E$42-$E$44)+$E$44) -> 1.1431497 | H34: =$C$51*$H$42+B34*(1-$H$42)^2/(B34*(1-$H$42-$H$44)+$H$44) -> 4.38 | I34: =120*PI()*$B$51/($H$37*SQRT(H34)) -> 44.257515
A35: test | B35: 1 | C35: =($C$42^2/($C$42/$C$51))+($C$44^2/($C$44/B35)) -> 3.1466788 | D35: =$C$51*$D$42+B35*((1-$D$42)^2)/(B35*(1-$D$42-$D$44)+$D$44) -> 3.3556623 | E35: =$C$51*$E$42+B35*((1-$E$42)^2)/(B35*(1-$E$42-$E$44)+$E$44) -> 1.1431489 | H35: =$C$51*$H$42+B35*(1-$H$42)^2/(B35*(1-$H$42-$H$44)+$H$44) -> 3.3556623 | I35: =120*PI()*$B$51/($H$37*SQRT(H35)) -> 50.563247
C36: W_eff | D36: W_eff | H36: W_eff
C37: =A51+(2*B51/PI())*LN(17.08*(A51/(2*B51)+0.92)) -> 0.0020676201 | D37: =A51+(2*B51/PI())*LN(17.08*(A51/(2*B51)+0.92)) -> 0.0020676201 | H37: =A51+(2*B51/PI())*LN(17.08*(A51/(2*B51)+0.92)) -> 0.0020676201
C38: H_1 | D38: v_e | H38: V_e
C39: =B51/B51 -> 1 | D39: =(2*$B$51/PI())*ATAN((PI()/((PI()*D37)/(2*$B$51)-2))*(($E$51/$B$51)-1)) -> 0.0005079977 | H39: =(2*$B$51/PI())*ATAN((PI()/((PI()*H37)/(2*$B$51)-2))*(($E$51/$B$51)-1)) -> 0.0005079977
C41: q_1 | D41: q_1 | E41: q_1 | H41: q_1
C42: =($C$39/2)*(1+PI()/4-($B$51/C37)*LN((2*C37/$B$51)*SIN($C$39*PI()/2)/$C$39+COS($C$39*PI()/2))) -> 0.63511207 | D42: =1-0.5*(B51/$D$37)*LN((PI()*$D$37/B51)-1) -> 0.69694151 | E42: =0.5+0.9/(PI()*LN(B51/A51)) -> 0.04235175 | H42: =1-0.5*($B$51/$H$37)*LN((PI()*$H$37/$B$51)-1) -> 0.69694151
C43: q_2 | D43: q_2 | E43: q_2 | H43: q_2
C44: =1-C42 -> 0.36488793 | D44: =1-D42 -> 0.30305849 | E44: =(0.9+(PI()/4)*LN((E51/B51+1)/(E51/B51+A51/(4*B51)-1)))/(PI()*LN(8*B51/A51))*ACOS((1-(B51/E51)*(1-A51/(8*B51)))*SQRT((E51/B51+1)/(E51/B51+A51/(4*B51)-1))) -> 9.7354012e-07 | H44: =1-H42-0.5*((B51-H39)/H37)*LN((PI()*H37/B51)*(COS(H39*PI()/(2*B51)))/(PI()*(E51/B51-0.5)+(H39*PI()/(2*B51)))+SIN(H39*PI()/(2*B51))) -> 0.30305849
A50: W | B50: h | C50: e_sub | D50: MUT Thickness (t_2) | E50: Total Height (h_2)
A51: =0.00095 -> 0.00095 | B51: =0.000508 -> 0.000508 | C51: 4.38 | D51: 100 | E51: =B51+D51 -> 100.00051
Q52: =60*LN((8*B51/A51)+0.25*(A51/B51)) -> 93.430726 | S52: =(C51+1)/2+(C51-1)/2*(1+10*(B51/A51))^(-0.5) -> 3.3607951

Sheet Calculo de Fase H2O
D1: length
D2: =0.25 -> 0.25 | F2: =0.5 -> 0.5 | H2: =0.612 -> 0.612 | J2: 0.01 | L2: =0.75 -> 0.75 | N2: =1 -> 1
A3: RH [%] | B3: ΕMUT | C3: εEFF | D3: θ | E3: Δθ | F3: θ2 | G3: Δθ2 | H3: θ3 | I3: Δθ3 | J3: θ4 | K3: Δθ4 | L3: θ5 | M3: Δθ5 | N3: θ6 | O3: Δθ6
A4: ='H2O Calculations'!A8 -> 0 | B4: ='Calculo de Dk H2O'!B5 -> 1.0005378 | C4: ='Calculo de Dk H2O'!D5 -> 3.3558253 | D4: =$D$2*360*$D$37*SQRT(C4*1)/$E$37 -> 2749.739 | E4: =D4-$D$4 -> 0 | F4: =$F$2*360*$D$37*SQRT(C4*1)/$E$37 -> 5499.4781 | G4: =F4-$F$4 -> 0 | H4: =$H$2*360*$D$37*SQRT(C4*1)/$E$37 -> 6731.3612 | I4: =H4-$H$4 -> 0 | J4: =$J$2*360*$D$37*SQRT(C4*1)/$E$37 -> 109.98956 | K4: =J4-$J$4 -> 0 | L4: =$L$2*360*$D$37*SQRT(C4*1)/$E$37 -> 8249.2171 | M4: =L4-$L$4 -> 0 | N4: =$N$2*360*$D$37*SQRT(C4*1)/$E$37 -> 10998.956 | O4: =N4-$N$4 -> 0 | Q4: 3.3558253
A5: ='H2O Calculations'!A9 -> 0.1 | B5: ='Calculo de Dk H2O'!B6 -> 1.0006281 | C5: ='Calculo de Dk H2O'!D6 -> 3.3558527 | D5: =$D$2*360*$D$37*SQRT(C5*1)/$E$37 -> 2749.7503 | E5: =D5-$D$4 -> 0.011215094 | F5: =$F$2*360*$D$37*SQRT(C5*1)/$E$37 -> 5499.5005 | G5: =F5-$F$4 -> 0.022430189 | H5: =$H$2*360*$D$37*SQRT(C5*1)/$E$37 -> 6731.3886 | I5: =H5-$H$4 -> 0.027454551 | J5: =$J$2*360*$D$37*SQRT(C5*1)/$E$37 -> 109.99001 | K5: =J5-$J$4 -> 0.00044860377 | L5: =$L$2*360*$D$37*SQRT(C5*1)/$E$37 -> 8249.2508 | M5: =L5-$L$4 -> 0.033645283 | N5: =$N$2*360*$D$37*SQRT(C5*1)/$E$37 -> 10999.001 | O5: =N5-$N$4 -> 0.044860377 | Q5: 3.3559177
A6: ='H2O Calculations'!A10 -> 0.2 | B6: ='Calculo de Dk H2O'!B7 -> 1.0007185 | C6: ='Calculo de Dk H2O'!D7 -> 3.35588 | D6: =$D$2*360*$D$37*SQRT(C6*1)/$E$37 -> 2749.7615 | E6: =D6-$D$4 -> 0.022430818 | F6: =$F$2*360*$D$37*SQRT(C6*1)/$E$37 -> 5499.523 | G6: =F6-$F$4 -> 0.044861636 | H6: =$H$2*360*$D$37*SQRT(C6*1)/$E$37 -> 6731.4161 | I6: =H6-$H$4 -> 0.054910643 | J6: =$J$2*360*$D$37*SQRT(C6*1)/$E$37 -> 109.99046 | K6: =J6-$J$4 -> 0.00089723272 | L6: =$L$2*360*$D$37*SQRT(C6*1)/$E$37 -> 8249.2844 | M6: =L6-$L$4 -> 0.067292454 | N6: =$N$2*360*$D$37*SQRT(C6*1)/$E$37 -> 10999.046 | O6: =N6-$N$4 -> 0.089723272 | Q6: 3.3567504
A7: ='H2O Calculations'!A11 -> 0.3 | B7: ='Calculo de Dk H2O'!B8 -> 1.0008088 | C7: ='Calculo de Dk H2O'!D8 -> 3.3559074 | D7: =$D$2*360*$D$37*SQRT(C7*1)/$E$37 -> 2749.7727 | E7: =D7-$D$4 -> 0.033647171 | F7: =$F$2*360*$D$37*SQRT(C7*1)/$E$37 -> 5499.5454 | G7: =F7-$F$4 -> 0.067294343 | H7: =$H$2*360*$D$37*SQRT(C7*1)/$E$37 -> 6731.4436 | I7: =H7-$H$4 -> 0.082368276 | J7: =$J$2*360*$D$37*SQRT(C7*1)/$E$37 -> 109.99091 | K7: =J7-$J$4 -> 0.0013458869 | L7: =$L$2*360*$D$37*SQRT(C7*1)/$E$37 -> 8249.3181 | M7: =L7-$L$4 -> 0.10094151 | N7: =$N$2*360*$D$37*SQRT(C7*1)/$E$37 -> 10999.091 | O7: =N7-$N$4 -> 0.13458869 | Q7: 3.3651619
A8: ='H2O Calculations'!A12 -> 0.4 | B8: ='Calculo de Dk H2O'!B9 -> 1.0008991 | C8: ='Calculo de Dk H2O'!D9 -> 3.3559348 | D8: =$D$2*360*$D$37*SQRT(C8*1)/$E$37 -> 2749.7839 | E8: =D8-$D$4 -> 0.044864154 | F8: =$F$2*360*$D$37*SQRT(C8*1)/$E$37 -> 5499.5678 | G8: =F8-$F$4 -> 0.089728309 | H8: =$H$2*360*$D$37*SQRT(C8*1)/$E$37 -> 6731.471 | I8: =H8-$H$4 -> 0.10982745 | J8: =$J$2*360*$D$37*SQRT(C8*1)/$E$37 -> 109.99136 | K8: =J8-$J$4 -> 0.0017945662 | L8: =$L$2*360*$D$37*SQRT(C8*1)/$E$37 -> 8249.3517 | M8: =L8-$L$4 -> 0.13459246 | N8: =$N$2*360*$D$37*SQRT(C8*1)/$E$37 -> 10999.136 | O8: =N8-$N$4 -> 0.17945662 | Q8: 3.4580124
A9: ='H2O Calculations'!A13 -> 0.5 | B9: ='Calculo de Dk H2O'!B10 -> 1.0009895 | C9: ='Calculo de Dk H2O'!D10 -> 3.3559622 | D9: =$D$2*360*$D$37*SQRT(C9*1)/$E$37 -> 2749.7951 | E9: =D9-$D$4 -> 0.056081767 | F9: =$F$2*360*$D$37*SQRT(C9*1)/$E$37 -> 5499.5903 | G9: =F9-$F$4 -> 0.11216353 | H9: =$H$2*360*$D$37*SQRT(C9*1)/$E$37 -> 6731.4985 | I9: =H9-$H$4 -> 0.13728817 | J9: =$J$2*360*$D$37*SQRT(C9*1)/$E$37 -> 109.99181 | K9: =J9-$J$4 -> 0.0022432707 | L9: =$L$2*360*$D$37*SQRT(C9*1)/$E$37 -> 8249.3854 | M9: =L9-$L$4 -> 0.1682453 | N9: =$N$2*360*$D$37*SQRT(C9*1)/$E$37 -> 10999.181 | O9: =N9-$N$4 -> 0.22432707
A10: ='H2O Calculations'!A14 -> 0.6 | B10: ='Calculo de Dk H2O'!B11 -> 1.0010798 | C10: ='Calculo de Dk H2O'!D11 -> 3.3559895 | D10: =$D$2*360*$D$37*SQRT(C10*1)/$E$37 -> 2749.8063 | E10: =D10-$D$4 -> 0.067300009 | F10: =$F$2*360*$D$37*SQRT(C10*1)/$E$37 -> 5499.6127 | G10: =F10-$F$4 -> 0.13460002 | H10: =$H$2*360*$D$37*SQRT(C10*1)/$E$37 -> 6731.5259 | I10: =H10-$H$4 -> 0.16475042 | J10: =$J$2*360*$D$37*SQRT(C10*1)/$E$37 -> 109.99225 | K10: =J10-$J$4 -> 0.0026920004 | L10: =$L$2*360*$D$37*SQRT(C10*1)/$E$37 -> 8249.419 | M10: =L10-$L$4 -> 0.20190003 | N10: =$N$2*360*$D$37*SQRT(C10*1)/$E$37 -> 10999.225 | O10: =N10-$N$4 -> 0.26920004
A11: ='H2O Calculations'!A15 -> 0.7 | B11: ='Calculo de Dk H2O'!B12 -> 1.0011702 | C11: ='Calculo de Dk H2O'!D12 -> 3.3560169 | D11: =$D$2*360*$D$37*SQRT(C11*1)/$E$37 -> 2749.8176 | E11: =D11-$D$4 -> 0.078518881 | F11: =$F$2*360*$D$37*SQRT(C11*1)/$E$37 -> 5499.6351 | G11: =F11-$F$4 -> 0.15703776 | H11: =$H$2*360*$D$37*SQRT(C11*1)/$E$37 -> 6731.5534 | I11: =H11-$H$4 -> 0.19221422 | J11: =$J$2*360*$D$37*SQRT(C11*1)/$E$37 -> 109.9927 | K11: =J11-$J$4 -> 0.0031407553 | L11: =$L$2*360*$D$37*SQRT(C11*1)/$E$37 -> 8249.4527 | M11: =L11-$L$4 -> 0.23555664 | N11: =$N$2*360*$D$37*SQRT(C11*1)/$E$37 -> 10999.27 | O11: =N11-$N$4 -> 0.31407553
A12: ='H2O Calculations'!A16 -> 0.8 | B12: ='Calculo de Dk H2O'!B13 -> 1.0012606 | C12: ='Calculo de Dk H2O'!D13 -> 3.3560443 | D12: =$D$2*360*$D$37*SQRT(C12*1)/$E$37 -> 2749.8288 | E12: =D12-$D$4 -> 0.089738383 | F12: =$F$2*360*$D$37*SQRT(C12*1)/$E$37 -> 5499.6576 | G12: =F12-$F$4 -> 0.17947677 | H12: =$H$2*360*$D$37*SQRT(C12*1)/$E$37 -> 6731.5809 | I12: =H12-$H$4 -> 0.21967956 | J12: =$J$2*360*$D$37*SQRT(C12*1)/$E$37 -> 109.99315 | K12: =J12-$J$4 -> 0.0035895353 | L12: =$L$2*360*$D$37*SQRT(C12*1)/$E$37 -> 8249.4864 | M12: =L12-$L$4 -> 0.26921515 | N12: =$N$2*360*$D$37*SQRT(C12*1)/$E$37 -> 10999.315 | O12: =N12-$N$4 -> 0.35895353
A13: ='H2O Calculations'!A17 -> 0.9 | B13: ='Calculo de Dk H2O'!B14 -> 1.0013509 | C13: ='Calculo de Dk H2O'!D14 -> 3.3560717 | D13: =$D$2*360*$D$37*SQRT(C13*1)/$E$37 -> 2749.84 | E13: =D13-$D$4 -> 0.10095852 | F13: =$F$2*360*$D$37*SQRT(C13*1)/$E$37 -> 5499.68 | G13: =F13-$F$4 -> 0.20191703 | H13: =$H$2*360*$D$37*SQRT(C13*1)/$E$37 -> 6731.6083 | I13: =H13-$H$4 -> 0.24714644 | J13: =$J$2*360*$D$37*SQRT(C13*1)/$E$37 -> 109.9936 | K13: =J13-$J$4 -> 0.0040383406 | L13: =$L$2*360*$D$37*SQRT(C13*1)/$E$37 -> 8249.52 | M13: =L13-$L$4 -> 0.30287555 | N13: =$N$2*360*$D$37*SQRT(C13*1)/$E$37 -> 10999.36 | O13: =N13-$N$4 -> 0.40383406
A14: ='H2O Calculations'!A18 -> 1 | B14: ='Calculo de Dk H2O'!B15 -> 1.0014413 | C14: ='Calculo de Dk H2O'!D15 -> 3.3560991 | D14: =$D$2*360*$D$37*SQRT(C14*1)/$E$37 -> 2749.8512 | E14: =D14-$D$4 -> 0.11217928 | F14: =$F$2*360*$D$37*SQRT(C14*1)/$E$37 -> 5499.7025 | G14: =F14-$F$4 -> 0.22435855 | H14: =$H$2*360*$D$37*SQRT(C14*1)/$E$37 -> 6731.6358 | I14: =H14-$H$4 -> 0.27461487 | J14: =$J$2*360*$D$37*SQRT(C14*1)/$E$37 -> 109.99405 | K14: =J14-$J$4 -> 0.0044871711 | L14: =$L$2*360*$D$37*SQRT(C14*1)/$E$37 -> 8249.5537 | M14: =L14-$L$4 -> 0.33653783 | N14: =$N$2*360*$D$37*SQRT(C14*1)/$E$37 -> 10999.405 | O14: =N14-$N$4 -> 0.44871711
A15: ='H2O Calculations'!A19 -> 2 | B15: ='Calculo de Dk H2O'!B16 -> 1.0023454 | C15: ='Calculo de Dk H2O'!D16 -> 3.3563731 | D15: =$D$2*360*$D$37*SQRT(C15*1)/$E$37 -> 2749.9635 | E15: =D15-$D$4 -> 0.22442155 | F15: =$F$2*360*$D$37*SQRT(C15*1)/$E$37 -> 5499.9269 | G15: =F15-$F$4 -> 0.4488431 | H15: =$H$2*360*$D$37*SQRT(C15*1)/$E$37 -> 6731.9106 | I15: =H15-$H$4 -> 0.54938396 | J15: =$J$2*360*$D$37*SQRT(C15*1)/$E$37 -> 109.99854 | K15: =J15-$J$4 -> 0.0089768621 | L15: =$L$2*360*$D$37*SQRT(C15*1)/$E$37 -> 8249.8904 | M15: =L15-$L$4 -> 0.67326465 | N15: =$N$2*360*$D$37*SQRT(C15*1)/$E$37 -> 10999.854 | O15: =N15-$N$4 -> 0.89768621
A16: ='H2O Calculations'!A20 -> 3 | B16: ='Calculo de Dk H2O'!B17 -> 1.00325 | C16: ='Calculo de Dk H2O'!D17 -> 3.3566472 | D16: =$D$2*360*$D$37*SQRT(C16*1)/$E$37 -> 2750.0758 | E16: =D16-$D$4 -> 0.33672688 | F16: =$F$2*360*$D$37*SQRT(C16*1)/$E$37 -> 5500.1516 | G16: =F16-$F$4 -> 0.67345376 | H16: =$H$2*360*$D$37*SQRT(C16*1)/$E$37 -> 6732.1855 | I16: =H16-$H$4 -> 0.8243074 | J16: =$J$2*360*$D$37*SQRT(C16*1)/$E$37 -> 110.00303 | K16: =J16-$J$4 -> 0.013469075 | L16: =$L$2*360*$D$37*SQRT(C16*1)/$E$37 -> 8250.2273 | M16: =L16-$L$4 -> 1.0101806 | N16: =$N$2*360*$D$37*SQRT(C16*1)/$E$37 -> 11000.303 | O16: =N16-$N$4 -> 1.3469075
A17: ='H2O Calculations'!A21 -> 4 | B17: ='Calculo de Dk H2O'!B18 -> 1.0041551 | C17: ='Calculo de Dk H2O'!D18 -> 3.3569215 | D17: =$D$2*360*$D$37*SQRT(C17*1)/$E$37 -> 2750.1881 | E17: =D17-$D$4 -> 0.44909531 | F17: =$F$2*360*$D$37*SQRT(C17*1)/$E$37 -> 5500.3763 | G17: =F17-$F$4 -> 0.89819062 | H17: =$H$2*360*$D$37*SQRT(C17*1)/$E$37 -> 6732.4606 | I17: =H17-$H$4 -> 1.0993853 | J17: =$J$2*360*$D$37*SQRT(C17*1)/$E$37 -> 110.00753 | K17: =J17-$J$4 -> 0.017963812 | L17: =$L$2*360*$D$37*SQRT(C17*1)/$E$37 -> 8250.5644 | M17: =L17-$L$4 -> 1.3472859 | N17: =$N$2*360*$D$37*SQRT(C17*1)/$E$37 -> 11000.753 | O17: =N17-$N$4 -> 1.7963812
A18: ='H2O Calculations'!A22 -> 5 | B18: ='Calculo de Dk H2O'!B19 -> 1.0050608 | C18: ='Calculo de Dk H2O'!D19 -> 3.357196 | D18: =$D$2*360*$D$37*SQRT(C18*1)/$E$37 -> 2750.3006 | E18: =D18-$D$4 -> 0.5615269 | F18: =$F$2*360*$D$37*SQRT(C18*1)/$E$37 -> 5500.6012 | G18: =F18-$F$4 -> 1.1230538 | H18: =$H$2*360*$D$37*SQRT(C18*1)/$E$37 -> 6732.7358 | I18: =H18-$H$4 -> 1.3746178 | J18: =$J$2*360*$D$37*SQRT(C18*1)/$E$37 -> 110.01202 | K18: =J18-$J$4 -> 0.022461076 | L18: =$L$2*360*$D$37*SQRT(C18*1)/$E$37 -> 8250.9017 | M18: =L18-$L$4 -> 1.6845807 | N18: =$N$2*360*$D$37*SQRT(C18*1)/$E$37 -> 11001.202 | O18: =N18-$N$4 -> 2.2461076
A19: ='H2O Calculations'!A23 -> 6 | B19: ='Calculo de Dk H2O'!B20 -> 1.005967 | C19: ='Calculo de Dk H2O'!D20 -> 3.3574707 | D19: =$D$2*360*$D$37*SQRT(C19*1)/$E$37 -> 2750.4131 | E19: =D19-$D$4 -> 0.6740217 | F19: =$F$2*360*$D$37*SQRT(C19*1)/$E$37 -> 5500.8261 | G19: =F19-$F$4 -> 1.3480434 | H19: =$H$2*360*$D$37*SQRT(C19*1)/$E$37 -> 6733.0112 | I19: =H19-$H$4 -> 1.6500051 | J19: =$J$2*360*$D$37*SQRT(C19*1)/$E$37 -> 110.01652 | K19: =J19-$J$4 -> 0.026960868 | L19: =$L$2*360*$D$37*SQRT(C19*1)/$E$37 -> 8251.2392 | M19: =L19-$L$4 -> 2.0220651 | N19: =$N$2*360*$D$37*SQRT(C19*1)/$E$37 -> 11001.652 | O19: =N19-$N$4 -> 2.6960868
A20: ='H2O Calculations'!A24 -> 7 | B20: ='Calculo de Dk H2O'!B21 -> 1.0068738 | C20: ='Calculo de Dk H2O'!D21 -> 3.3577455 | D20: =$D$2*360*$D$37*SQRT(C20*1)/$E$37 -> 2750.5256 | E20: =D20-$D$4 -> 0.78657977 | F20: =$F$2*360*$D$37*SQRT(C20*1)/$E$37 -> 5501.0513 | G20: =F20-$F$4 -> 1.5731595 | H20: =$H$2*360*$D$37*SQRT(C20*1)/$E$37 -> 6733.2867 | I20: =H20-$H$4 -> 1.9255473 | J20: =$J$2*360*$D$37*SQRT(C20*1)/$E$37 -> 110.02103 | K20: =J20-$J$4 -> 0.031463191 | L20: =$L$2*360*$D$37*SQRT(C20*1)/$E$37 -> 8251.5769 | M20: =L20-$L$4 -> 2.3597393 | N20: =$N$2*360*$D$37*SQRT(C20*1)/$E$37 -> 11002.103 | O20: =N20-$N$4 -> 3.1463191
... A32: ='H2O Calculations'!A36 -> 100 | B32: ='Calculo de Dk H2O'!B33 -> 1.0936649 | C32: ='Calculo de Dk H2O'!D33 -> 3.3840482 | D32: =$D$2*360*$D$37*SQRT(C32*1)/$E$37 -> 2761.2777 | E32: =D32-$D$4 -> 11.538641 | F32: =$F$2*360*$D$37*SQRT(C32*1)/$E$37 -> 5522.5554 | G32: =F32-$F$4 -> 23.077282 | H32: =$H$2*360*$D$37*SQRT(C32*1)/$E$37 -> 6759.6078 | I32: =H32-$H$4 -> 28.246593 | J32: =$J$2*360*$D$37*SQRT(C32*1)/$E$37 -> 110.45111 | K32: =J32-$J$4 -> 0.46154564 | L32: =$L$2*360*$D$37*SQRT(C32*1)/$E$37 -> 8283.8331 | M32: =L32-$L$4 -> 34.615923 | N32: =$N$2*360*$D$37*SQRT(C32*1)/$E$37 -> 11045.111 | O32: =N32-$N$4 -> 46.154564
D36: Freq | E36: c
D37: =5000000000 -> 5000000000 | E37: =299792458 -> 299792458
D43: =0.000006055611 -> 6.055611e-06 | E43: =D43*D2 -> 1.5139028e-06 | F43: ms
H44: 0.01 | I44: 0.612
D45: Vin | E45: =1/SQRT(2) -> 0.70710678 | H45: θ | I45: θ | J45: Δθ | K45: Δθ
H46: =$H$44*360*$D$37*SQRT(C4*1)/$E$37 -> 109.98956 | I46: =$I$44*360*$D$37*SQRT(C4*1)/$E$37 -> 6731.3612 | J46: =I46-H46 -> 6621.3716 | K46: =MOD(J46,360) -> 141.37163 | L46: =ABS(SQRT(2)*$E$45*COS((K46*PI()/180)/2)) -> 0.33074803 | M46: =$L$46-L46 -> 0
H47: =$H$44*360*$D$37*SQRT(C5*1)/$E$37 -> 109.99001 | I47: =$I$44*360*$D$37*SQRT(C5*1)/$E$37 -> 6731.3886 | J47: =I47-H47 -> 6621.3986 | K47: =MOD(J47,360) -> 141.39864 | L47: =ABS(SQRT(2)*$E$45*COS((K47*PI()/180)/2)) -> 0.33052561 | M47: =$L$46-L47 -> 0.00022241673
H48: =$H$44*360*$D$37*SQRT(C14*1)/$E$37 -> 109.99405 | I48: =$I$44*360*$D$37*SQRT(C14*1)/$E$37 -> 6731.6358 | J48: =I48-H48 -> 6621.6418 | K48: =MOD(J48,360) -> 141.64176 | L48: =ABS(SQRT(2)*$E$45*COS((K48*PI()/180)/2)) -> 0.32852247 | M48: =$L$46-L48 -> 0.0022255543
H49: =$H$44*360*$D$37*SQRT(C23*1)/$E$37 -> 110.03455 | I49: =$I$44*360*$D$37*SQRT(C23*1)/$E$37 -> 6734.1143 | J49: =I49-H49 -> 6624.0798 | K49: =MOD(J49,360) -> 144.07975 | L49: =ABS(SQRT(2)*$E$45*COS((K49*PI()/180)/2)) -> 0.30835502 | M49: =$L$46-L49 -> 0.022393003
H50: =$H$44*360*$D$37*SQRT(C32*1)/$E$37 -> 110.45111 | I50: =$I$44*360*$D$37*SQRT(C32*1)/$E$37 -> 6759.6078 | J50: =I50-H50 -> 6649.1567 | K50: =MOD(J50,360) -> 169.15668 | L50: =ABS(SQRT(2)*$E$45*COS((K50*PI()/180)/2)) -> 0.09448467 | M50: =$L$46-L50 -> 0.23626336
E53: 0.01 | F53: 0.612
E54: θ | F54: θ | G54: Δθ | H54: Δθmod | I54: Vcomb
E55: =$H$44*360*$D$37*SQRT(C4*1)/$E$37 -> 109.98956 | F55: =$I$44*360*$D$37*SQRT(C4*1)/$E$37 -> 6731.3612 | G55: =F55-E55 -> 6621.3716 | H55: =MOD(G55,360) -> 141.37163 | I55: =ABS(SQRT(2)*$E$45*COS((H55*PI()/180)/2)) -> 0.33074803 | K55: 90 | L55: =ABS(SQRT(2)*$E$45*COS((K55*PI()/180)/2)) -> 0.70710678
E56: =$H$44*360*$D$37*SQRT(C5*1)/$E$37 -> 109.99001 | F56: =$I$44*360*$D$37*SQRT(C5*1)/$E$37 -> 6731.3886 | G56: =F56-E56 -> 6621.3986 | H56: =MOD(G56,360) -> 141.39864 | I56: =ABS(SQRT(2)*$E$45*COS((H56*PI()/180)/2)) -> 0.33052561 | K56: =K55+1 -> 91 | L56: =ABS(SQRT(2)*$E$45*COS((K56*PI()/180)/2)) -> 0.70090926
E57: =$H$44*360*$D$37*SQRT(C6*1)/$E$37 -> 109.99046 | F57: =$I$44*360*$D$37*SQRT(C6*1)/$E$37 -> 6731.4161 | G57: =F57-E57 -> 6621.4256 | H57: =MOD(G57,360) -> 141.42565 | I57: =ABS(SQRT(2)*$E$45*COS((H57*PI()/180)/2)) -> 0.33030316 | K57: =K56+1 -> 92 | L57: =ABS(SQRT(2)*$E$45*COS((K57*PI()/180)/2)) -> 0.69465837
E58: =$H$44*360*$D$37*SQRT(C7*1)/$E$37 -> 109.99091 | F58: =$I$44*360*$D$37*SQRT(C7*1)/$E$37 -> 6731.4436 | G58: =F58-E58 -> 6621.4527 | H58: =MOD(G58,360) -> 141.45265 | I58: =ABS(SQRT(2)*$E$45*COS((H58*PI()/180)/2)) -> 0.33008068 | K58: =K57+1 -> 93 | L58: =ABS(SQRT(2)*$E$45*COS((K58*PI()/180)/2)) -> 0.68835458
E59: =$H$44*360*$D$37*SQRT(C8*1)/$E$37 -> 109.99136 | F59: =$I$44*360*$D$37*SQRT(C8*1)/$E$37 -> 6731.471 | G59: =F59-E59 -> 6621.4797 | H59: =MOD(G59,360) -> 141.47966 | I59: =ABS(SQRT(2)*$E$45*COS((H59*PI()/180)/2)) -> 0.32985818 | K59: =K58+1 -> 94 | L59: =ABS(SQRT(2)*$E$45*COS((K59*PI()/180)/2)) -> 0.68199836
E60: =$H$44*360*$D$37*SQRT(C9*1)/$E$37 -> 109.99181 | F60: =$I$44*360*$D$37*SQRT(C9*1)/$E$37 -> 6731.4985 | G60: =F60-E60 -> 6621.5067 | H60: =MOD(G60,360) -> 141.50668 | I60: =ABS(SQRT(2)*$E$45*COS((H60*PI()/180)/2)) -> 0.32963564 | K60: =K59+1 -> 95 | L60: =ABS(SQRT(2)*$E$45*COS((K60*PI()/180)/2)) -> 0.67559021
E61: =$H$44*360*$D$37*SQRT(C10*1)/$E$37 -> 109.99225 | F61: =$I$44*360*$D$37*SQRT(C10*1)/$E$37 -> 6731.5259 | G61: =F61-E61 -> 6621.5337 | H61: =MOD(G61,360) -> 141.53369 | I61: =ABS(SQRT(2)*$E$45*COS((H61*PI()/180)/2)) -> 0.32941306 | K61: =K60+1 -> 96 | L61: =ABS(SQRT(2)*$E$45*COS((K61*PI()/180)/2)) -> 0.66913061
...

Sheet Acetone Calculations
G2: Power Law Formulations | O2: Unified Mixing Rule | AA2: Virial Based Mixing Rule
G3: Silberstein Formula Linear Law | I3: Birchak Formula Square Root Law | K3: Looyenga Formula Cubic Root Law | M3: Generalized Power Law | O3: Maxwell Garnett Rule | Q3: Polder-van Santen Formula | S3: Coherent Potential Approximation | U3: Generalized Unified Mixing Rule
G4: (β=1) | I4: (β=1/2) | K4: (β=1/3) | M4: 0.33 | O4: (ν=0) | Q4: (ν=2) | S4: (ν=3) | Y4: 0 | AB4: =($E$40/($E$60*$E$43)) -> 40.873998
A7: RH [%] | C7: rmol [ppm] | D7: XH2O [mol/mol] | E7: XAir [mol/mol] | G7: εr [1] | I7: εr [2] | K7: εr [3] | M7: εr [4] | O7: Column1 | Q7: Column1 | S7: Column1 | U7: a | V7: b | W7: c | X7: x | Y7: εr [5] | AA7: BMIX | AB7: ρMIX | AC7: Πmix | AD7: εr [6] | AF7: Πmix | AG7: εr [6]
A8: 0 | C8: =1000000*(A8/100)*$E$45/$E$41 -> 0 | D8: =C8/10000 -> 0 | E8: =1-D8 -> 1 | G8: =E8*$E$57+D8*$E$46 -> 1.0005378 | I8: =(E8*$E$57^(1/2)+D8*$E$46^(1/2))^2 -> 1.0005378 | K8: =(E8*$E$57^(1/3)+D8*$E$46^(1/3))^3 -> 1.0005378 | M8: =(E8*$E$57^($M$4)+D8*$E$46^($M$4))^(1/$M$4) -> 1.0005378 | O8: =$E$57+3*D8*$E$57*(($E$46-$E$57)/($E$46+2*$E$57-D8*($E$46-$E$57))) -> 1.0005378 | U8: =$Y$4 -> 0 | V8: =$E$46*(1-D8*(1+$Y$4))+$E$57*(2+D8*(1+$Y$4)) -> 22.701076 | W8: =-($E$46-$E$57)*D8*3*$E$57 -> 0 | X8: =IF(U8=0,-W8/V8,(-V8+SQRT(V8^2-4*U8*W8))/2*U8) -> 0 | Y8: =X8+$E$57 -> 1.0005378 | AA8: =E8^2*$AB$48+2*E8*D8*$AB$50+D8^2*$AB$49 -> -7.6244426e-06 | AB8: =$E$40/(($E$60*$E$43)*(1+(AA9*$E$40/($E$60*$E$43)))) -> 40.886762 | AC8: =$E$56*E8+$E$47*D8 -> 4.3850492 | AD8: =(2*(AB8)*AC8*0.000001+1)/(1-(AB8)*AC8*0.000001) -> 1.000538 | AF8: =$E$56*E8+$E$47*D8 -> 4.3850492 | AG8: =(2*($E$40/($E$60*$E$43))*AF8*0.000001+1)/(1-($E$40/($E$60*$E$43))*AF8*0.000001) -> 1.0005378
A9: 0.1 | C9: =1000000*(A9/100)*$E$45/$E$41 -> 303.82964 | D9: =C9/1000000 -> 0.00030382964 | E9: =1-D9 -> 0.99969617 | G9: =E9*$E$57+D9*$E$46 -> 1.0065231 | I9: =(E9*$E$57^(1/2)+D9*$E$46^(1/2))^2 -> 1.0026964 | K9: =(E9*$E$57^(1/3)+D9*$E$46^(1/3))^3 -> 1.0021303 | M9: =(E9*$E$57^($M$4)+D9*$E$46^($M$4))^(1/$M$4) -> 1.0021209 | O9: =$E$57+3*D9*$E$57*(($E$46-$E$57)/($E$46+2*$E$57-D9*($E$46-$E$57))) -> 1.0013294 | U9: =$Y$4 -> 0 | V9: =$E$46*(1-D9*(1+$Y$4))+$E$57*(2+D9*(1+$Y$4)) -> 22.69509 | W9: =-($E$46-$E$57)*D9*3*$E$57 -> -0.017965498 | X9: =IF(U9=0,-W9/V9,(-V9+SQRT(V9^2-4*U9*W9))/2*U9) -> 0.00079160286 | Y9: =X9+$E$57 -> 1.0013294 | AA9: =E9^2*$AB$48+2*E9*D9*$AB$50+D9^2*$AB$49 -> -7.6375906e-06 | AB9: =$E$40/(($E$60*$E$43)*(1+(AA10*$E$40/($E$60*$E$43)))) -> 40.886784 | AC9: =$E$56*E9+$E$47*D9 -> 10.834663 | AD9: =(2*(AB9)*AC9*0.000001+1)/(1-(AB9)*AC9*0.000001) -> 1.0013296 | AF9: =$E$56*E9+$E$47*D9 -> 10.834663 | AG9: =(2*($E$40/($E$60*$E$43))*AF9*0.000001+1)/(1-($E$40/($E$60*$E$43))*AF9*0.000001) -> 1.0013292
A10: 0.2 | C10: =1000000*(A10/100)*$E$45/$E$41 -> 607.65929 | D10: =C10/1000000 -> 0.00060765929 | E10: =1-D10 -> 0.99939234 | G10: =E10*$E$57+D10*$E$46 -> 1.0125084 | I10: =(E10*$E$57^(1/2)+D10*$E$46^(1/2))^2 -> 1.0048573 | K10: =(E10*$E$57^(1/3)+D10*$E$46^(1/3))^3 -> 1.0037244 | M10: =(E10*$E$57^($M$4)+D10*$E$46^($M$4))^(1/$M$4) -> 1.0037057 | O10: =$E$57+3*D10*$E$57*(($E$46-$E$57)/($E$46+2*$E$57-D10*($E$46-$E$57))) -> 1.0021214 | U10: =$Y$4 -> 0 | V10: =$E$46*(1-D10*(1+$Y$4))+$E$57*(2+D10*(1+$Y$4)) -> 22.689105 | W10: =-($E$46-$E$57)*D10*3*$E$57 -> -0.035930997 | X10: =IF(U10=0,-W10/V10,(-V10+SQRT(V10^2-4*U10*W10))/2*U10) -> 0.0015836234 | Y10: =X10+$E$57 -> 1.0021214 | AA10: =E10^2*$AB$48+2*E10*D10*$AB$50+D10^2*$AB$49 -> -7.6507293e-06 | AB10: =$E$40/(($E$60*$E$43)*(1+(AA11*$E$40/($E$60*$E$43)))) -> 40.886806 | AC10: =$E$56*E10+$E$47*D10 -> 17.284276 | AD10: =(2*(AB10)*AC10*0.000001+1)/(1-(AB10)*AC10*0.000001) -> 1.0021216 | AF10: =$E$56*E10+$E$47*D10 -> 17.284276 | AG10: =(2*($E$40/($E$60*$E$43))*AF10*0.000001+1)/(1-($E$40/($E$60*$E$43))*AF10*0.000001) -> 1.0021209
A11: 0.3 | C11: =1000000*(A11/100)*$E$45/$E$41 -> 911.48893 | D11: =C11/1000000 -> 0.00091148893 | E11: =1-D11 -> 0.99908851 | G11: =E11*$E$57+D11*$E$46 -> 1.0184936 | I11: =(E11*$E$57^(1/2)+D11*$E$46^(1/2))^2 -> 1.0070206 | K11: =(E11*$E$57^(1/3)+D11*$E$46^(1/3))^3 -> 1.0053202 | M11: =(E11*$E$57^($M$4)+D11*$E$46^($M$4))^(1/$M$4) -> 1.0052922 | O11: =$E$57+3*D11*$E$57*(($E$46-$E$57)/($E$46+2*$E$57-D11*($E$46-$E$57))) -> 1.0029139 | U11: =$Y$4 -> 0 | V11: =$E$46*(1-D11*(1+$Y$4))+$E$57*(2+D11*(1+$Y$4)) -> 22.68312 | W11: =-($E$46-$E$57)*D11*3*$E$57 -> -0.053896495 | X11: =IF(U11=0,-W11/V11,(-V11+SQRT(V11^2-4*U11*W11))/2*U11) -> 0.0023760618 | Y11: =X11+$E$57 -> 1.0029139 | AA11: =E11^2*$AB$48+2*E11*D11*$AB$50+D11^2*$AB$49 -> -7.6638585e-06 | AB11: =$E$40/(($E$60*$E$43)*(1+(AA12*$E$40/($E$60*$E$43)))) -> 40.886828 | AC11: =$E$56*E11+$E$47*D11 -> 23.73389 | AD11: =(2*(AB11)*AC11*0.000001+1)/(1-(AB11)*AC11*0.000001) -> 1.002914 | AF11: =$E$56*E11+$E$47*D11 -> 23.73389 | AG11: =(2*($E$40/($E$60*$E$43))*AF11*0.000001+1)/(1-($E$40/($E$60*$E$43))*AF11*0.000001) -> 1.0029131
A12: 0.4 | C12: =1000000*(A12/100)*$E$45/$E$41 -> 1215.3186 | D12: =C12/1000000 -> 0.0012153186 | E12: =1-D12 -> 0.99878468 | G12: =E12*$E$57+D12*$E$46 -> 1.0244789 | I12: =(E12*$E$57^(1/2)+D12*$E$46^(1/2))^2 -> 1.0091862 | K12: =(E12*$E$57^(1/3)+D12*$E$46^(1/3))^3 -> 1.0069178 | M12: =(E12*$E$57^($M$4)+D12*$E$46^($M$4))^(1/$M$4) -> 1.0068803 | O12: =$E$57+3*D12*$E$57*(($E$46-$E$57)/($E$46+2*$E$57-D12*($E$46-$E$57))) -> 1.0037067 | U12: =$Y$4 -> 0 | V12: =$E$46*(1-D12*(1+$Y$4))+$E$57*(2+D12*(1+$Y$4)) -> 22.677134 | W12: =-($E$46-$E$57)*D12*3*$E$57 -> -0.071861993 | X12: =IF(U12=0,-W12/V12,(-V12+SQRT(V12^2-4*U12*W12))/2*U12) -> 0.0031689186 | Y12: =X12+$E$57 -> 1.0037067 | AA12: =E12^2*$AB$48+2*E12*D12*$AB$50+D12^2*$AB$49 -> -7.6769784e-06 | AB12: =$E$40/(($E$60*$E$43)*(1+(AA13*$E$40/($E$60*$E$43)))) -> 40.88685 | AC12: =$E$56*E12+$E$47*D12 -> 30.183503 | AD12: =(2*(AB12)*AC12*0.000001+1)/(1-(AB12)*AC12*0.000001) -> 1.0037069 | AF12: =$E$56*E12+$E$47*D12 -> 30.183503 | AG12: =(2*($E$40/($E$60*$E$43))*AF12*0.000001+1)/(1-($E$40/($E$60*$E$43))*AF12*0.000001) -> 1.0037057
A13: 0.5 | C13: =1000000*(A13/100)*$E$45/$E$41 -> 1519.1482 | D13: =C13/1000000 -> 0.0015191482 | E13: =1-D13 -> 0.99848085 | G13: =E13*$E$57+D13*$E$46 -> 1.0304642 | I13: =(E13*$E$57^(1/2)+D13*$E$46^(1/2))^2 -> 1.0113541 | K13: =(E13*$E$57^(1/3)+D13*$E$46^(1/3))^3 -> 1.008517 | M13: =(E13*$E$57^($M$4)+D13*$E$46^($M$4))^(1/$M$4) -> 1.0084702 | O13: =$E$57+3*D13*$E$57*(($E$46-$E$57)/($E$46+2*$E$57-D13*($E$46-$E$57))) -> 1.0045 | U13: =$Y$4 -> 0 | V13: =$E$46*(1-D13*(1+$Y$4))+$E$57*(2+D13*(1+$Y$4)) -> 22.671149 | W13: =-($E$46-$E$57)*D13*3*$E$57 -> -0.089827492 | X13: =IF(U13=0,-W13/V13,(-V13+SQRT(V13^2-4*U13*W13))/2*U13) -> 0.003962194 | Y13: =X13+$E$57 -> 1.0045 | AA13: =E13^2*$AB$48+2*E13*D13*$AB$50+D13^2*$AB$49 -> -7.6900888e-06 | AB13: =$E$40/(($E$60*$E$43)*(1+(AA14*$E$40/($E$60*$E$43)))) -> 40.886872 | AC13: =$E$56*E13+$E$47*D13 -> 36.633116 | AD13: =(2*(AB13)*AC13*0.000001+1)/(1-(AB13)*AC13*0.000001) -> 1.0045002 | AF13: =$E$56*E13+$E$47*D13 -> 36.633116 | AG13: =(2*($E$40/($E$60*$E$43))*AF13*0.000001+1)/(1-($E$40/($E$60*$E$43))*AF13*0.000001) -> 1.0044988
A14: 0.6 | C14: =1000000*(A14/100)*$E$45/$E$41 -> 1822.9779 | D14: =C14/1000000 -> 0.0018229779 | E14: =1-D14 -> 0.99817702 | G14: =E14*$E$57+D14*$E$46 -> 1.0364495 | I14: =(E14*$E$57^(1/2)+D14*$E$46^(1/2))^2 -> 1.0135243 | K14: =(E14*$E$57^(1/3)+D14*$E$46^(1/3))^3 -> 1.0101179 | M14: =(E14*$E$57^($M$4)+D14*$E$46^($M$4))^(1/$M$4) -> 1.0100617 | O14: =$E$57+3*D14*$E$57*(($E$46-$E$57)/($E$46+2*$E$57-D14*($E$46-$E$57))) -> 1.0052937 | U14: =$Y$4 -> 0 | V14: =$E$46*(1-D14*(1+$Y$4))+$E$57*(2+D14*(1+$Y$4)) -> 22.665164 | W14: =-($E$46-$E$57)*D14*3*$E$57 -> -0.10779299 | X14: =IF(U14=0,-W14/V14,(-V14+SQRT(V14^2-4*U14*W14))/2*U14) -> 0.0047558884 | Y14: =X14+$E$57 -> 1.0052937 | AA14: =E14^2*$AB$48+2*E14*D14*$AB$50+D14^2*$AB$49 -> -7.7031898e-06 | AB14: =$E$40/(($E$60*$E$43)*(1+(AA15*$E$40/($E$60*$E$43)))) -> 40.886894 | AC14: =$E$56*E14+$E$47*D14 -> 43.08273 | AD14: =(2*(AB14)*AC14*0.000001+1)/(1-(AB14)*AC14*0.000001) -> 1.0052939 | AF14: =$E$56*E14+$E$47*D14 -> 43.08273 | AG14: =(2*($E$40/($E$60*$E$43))*AF14*0.000001+1)/(1-($E$40/($E$60*$E$43))*AF14*0.000001) -> 1.0052922
A15: 0.7 | C15: =1000000*(A15/100)*$E$45/$E$41 -> 2126.8075 | D15: =C15/1000000 -> 0.0021268075 | E15: =1-D15 -> 0.99787319 | G15: =E15*$E$57+D15*$E$46 -> 1.0424348 | I15: =(E15*$E$57^(1/2)+D15*$E$46^(1/2))^2 -> 1.0156969 | K15: =(E15*$E$57^(1/3)+D15*$E$46^(1/3))^3 -> 1.0117205 | M15: =(E15*$E$57^($M$4)+D15*$E$46^($M$4))^(1/$M$4) -> 1.0116549 | O15: =$E$57+3*D15*$E$57*(($E$46-$E$57)/($E$46+2*$E$57-D15*($E$46-$E$57))) -> 1.0060878 | U15: =$Y$4 -> 0 | V15: =$E$46*(1-D15*(1+$Y$4))+$E$57*(2+D15*(1+$Y$4)) -> 22.659179 | W15: =-($E$46-$E$57)*D15*3*$E$57 -> -0.12575849 | X15: =IF(U15=0,-W15/V15,(-V15+SQRT(V15^2-4*U15*W15))/2*U15) -> 0.0055500021 | Y15: =X15+$E$57 -> 1.0060878 | AA15: =E15^2*$AB$48+2*E15*D15*$AB$50+D15^2*$AB$49 -> -7.7162815e-06 | AB15: =$E$40/(($E$60*$E$43)*(1+(AA16*$E$40/($E$60*$E$43)))) -> 40.886916 | AC15: =$E$56*E15+$E$47*D15 -> 49.532343 | AD15: =(2*(AB15)*AC15*0.000001+1)/(1-(AB15)*AC15*0.000001) -> 1.006088 | AF15: =$E$56*E15+$E$47*D15 -> 49.532343 | AG15: =(2*($E$40/($E$60*$E$43))*AF15*0.000001+1)/(1-($E$40/($E$60*$E$43))*AF15*0.000001) -> 1.0060861
A16: 0.8 | C16: =1000000*(A16/100)*$E$45/$E$41 -> 2430.6371 | D16: =C16/1000000 -> 0.0024306371 | E16: =1-D16 -> 0.99756936 | G16: =E16*$E$57+D16*$E$46 -> 1.04842 | I16: =(E16*$E$57^(1/2)+D16*$E$46^(1/2))^2 -> 1.0178718 | K16: =(E16*$E$57^(1/3)+D16*$E$46^(1/3))^3 -> 1.0133248 | M16: =(E16*$E$57^($M$4)+D16*$E$46^($M$4))^(1/$M$4) -> 1.0132498 | O16: =$E$57+3*D16*$E$57*(($E$46-$E$57)/($E$46+2*$E$57-D16*($E$46-$E$57))) -> 1.0068823 | U16: =$Y$4 -> 0 | V16: =$E$46*(1-D16*(1+$Y$4))+$E$57*(2+D16*(1+$Y$4)) -> 22.653193 | W16: =-($E$46-$E$57)*D16*3*$E$57 -> -0.14372399 | X16: =IF(U16=0,-W16/V16,(-V16+SQRT(V16^2-4*U16*W16))/2*U16) -> 0.0063445354 | Y16: =X16+$E$57 -> 1.0068823 | AA16: =E16^2*$AB$48+2*E16*D16*$AB$50+D16^2*$AB$49 -> -7.7293637e-06 | AB16: =$E$40/(($E$60*$E$43)*(1+(AA17*$E$40/($E$60*$E$43)))) -> 40.886938 | AC16: =$E$56*E16+$E$47*D16 -> 55.981957 | AD16: =(2*(AB16)*AC16*0.000001+1)/(1-(AB16)*AC16*0.000001) -> 1.0068825 | AF16: =$E$56*E16+$E$47*D16 -> 55.981957 | AG16: =(2*($E$40/($E$60*$E$43))*AF16*0.000001+1)/(1-($E$40/($E$60*$E$43))*AF16*0.000001) -> 1.0068804
A17: 0.9 | C17: =1000000*(A17/100)*$E$45/$E$41 -> 2734.4668 | D17: =C17/1000000 -> 0.0027344668 | E17: =1-D17 -> 0.99726553 | G17: =E17*$E$57+D17*$E$46 -> 1.0544053 | I17: =(E17*$E$57^(1/2)+D17*$E$46^(1/2))^2 -> 1.020049 | K17: =(E17*$E$57^(1/3)+D17*$E$46^(1/3))^3 -> 1.0149308 | M17: =(E17*$E$57^($M$4)+D17*$E$46^($M$4))^(1/$M$4) -> 1.0148463 | O17: =$E$57+3*D17*$E$57*(($E$46-$E$57)/($E$46+2*$E$57-D17*($E$46-$E$57))) -> 1.0076773 | U17: =$Y$4 -> 0 | V17: =$E$46*(1-D17*(1+$Y$4))+$E$57*(2+D17*(1+$Y$4)) -> 22.647208 | W17: =-($E$46-$E$57)*D17*3*$E$57 -> -0.16168948 | X17: =IF(U17=0,-W17/V17,(-V17+SQRT(V17^2-4*U17*W17))/2*U17) -> 0.0071394886 | Y17: =X17+$E$57 -> 1.0076773 | AA17: =E17^2*$AB$48+2*E17*D17*$AB$50+D17^2*$AB$49 -> -7.7424365e-06 | AB17: =$E$40/(($E$60*$E$43)*(1+(AA18*$E$40/($E$60*$E$43)))) -> 40.886959 | AC17: =$E$56*E17+$E$47*D17 -> 62.43157 | AD17: =(2*(AB17)*AC17*0.000001+1)/(1-(AB17)*AC17*0.000001) -> 1.0076775 | AF17: =$E$56*E17+$E$47*D17 -> 62.43157 | AG17: =(2*($E$40/($E$60*$E$43))*AF17*0.000001+1)/(1-($E$40/($E$60*$E$43))*AF17*0.000001) -> 1.0076751
A18: 1 | C18: =1000000*(A18/100)*$E$45/$E$41 -> 3038.2964 | D18: =C18/1000000 -> 0.0030382964 | E18: =1-D18 -> 0.9969617 | G18: =E18*$E$57+D18*$E$46 -> 1.0603906 | I18: =(E18*$E$57^(1/2)+D18*$E$46^(1/2))^2 -> 1.0222285 | K18: =(E18*$E$57^(1/3)+D18*$E$46^(1/3))^3 -> 1.0165385 | M18: =(E18*$E$57^($M$4)+D18*$E$46^($M$4))^(1/$M$4) -> 1.0164446 | O18: =$E$57+3*D18*$E$57*(($E$46-$E$57)/($E$46+2*$E$57-D18*($E$46-$E$57))) -> 1.0084727 | U18: =$Y$4 -> 0 | V18: =$E$46*(1-D18*(1+$Y$4))+$E$57*(2+D18*(1+$Y$4)) -> 22.641223 | W18: =-($E$46-$E$57)*D18*3*$E$57 -> -0.17965498 | X18: =IF(U18=0,-W18/V18,(-V18+SQRT(V18^2-4*U18*W18))/2*U18) -> 0.0079348622 | Y18: =X18+$E$57 -> 1.0084727 | AA18: =E18^2*$AB$48+2*E18*D18*$AB$50+D18^2*$AB$49 -> -7.7555e-06 | AB18: =$E$40/(($E$60*$E$43)*(1+(AA19*$E$40/($E$60*$E$43)))) -> 40.887177 | AC18: =$E$56*E18+$E$47*D18 -> 68.881183 | AD18: =(2*(AB18)*AC18*0.000001+1)/(1-(AB18)*AC18*0.000001) -> 1.0084729 | AF18: =$E$56*E18+$E$47*D18 -> 68.881183 | AG18: =(2*($E$40/($E$60*$E$43))*AF18*0.000001+1)/(1-($E$40/($E$60*$E$43))*AF18*0.000001) -> 1.0084702
A19: 2 | C19: =1000000*(A19/100)*$E$45/$E$41 -> 6076.5929 | D19: =C19/1000000 -> 0.0060765929 | E19: =1-D19 -> 0.99392341 | G19: =E19*$E$57+D19*$E$46 -> 1.1202434 | I19: =(E19*$E$57^(1/2)+D19*$E$46^(1/2))^2 -> 1.0441518 | K19: =(E19*$E$57^(1/3)+D19*$E$46^(1/3))^3 -> 1.0327089 | M19: =(E19*$E$57^($M$4)+D19*$E$46^($M$4))^(1/$M$4) -> 1.0325199 | O19: =$E$57+3*D19*$E$57*(($E$46-$E$57)/($E$46+2*$E$57-D19*($E$46-$E$57))) -> 1.0164496 | U19: =$Y$4 -> 0 | V19: =$E$46*(1-D19*(1+$Y$4))+$E$57*(2+D19*(1+$Y$4)) -> 22.58137 | W19: =-($E$46-$E$57)*D19*3*$E$57 -> -0.35930997 | X19: =IF(U19=0,-W19/V19,(-V19+SQRT(V19^2-4*U19*W19))/2*U19) -> 0.015911788 | Y19: =X19+$E$57 -> 1.0164496 | AA19: =E19^2*$AB$48+2*E19*D19*$AB$50+D19^2*$AB$49 -> -7.8856174e-06 | AB19: =$E$40/(($E$60*$E$43)*(1+(AA20*$E$40/($E$60*$E$43)))) -> 40.887393 | AC19: =$E$56*E19+$E$47*D19 -> 133.37732 | AD19: =(2*(AB19)*AC19*0.000001+1)/(1-(AB19)*AC19*0.000001) -> 1.0164501 | AF19: =$E$56*E19+$E$47*D19 -> 133.37732 | AG19: =(2*($E$40/($E$60*$E$43))*AF19*0.000001+1)/(1-($E$40/($E$60*$E$43))*AF19*0.000001) -> 1.0164446
A20: 3 | C20: =1000000*(A20/100)*$E$45/$E$41 -> 9114.8893 | D20: =C20/1000000 -> 0.0091148893 | E20: =1-D20 -> 0.99088511 | G20: =E20*$E$57+D20*$E$46 -> 1.1800962 | I20: =(E20*$E$57^(1/2)+D20*$E$46^(1/2))^2 -> 1.0663077 | K20: =(E20*$E$57^(1/3)+D20*$E$46^(1/3))^3 -> 1.0490498 | M20: =(E20*$E$57^($M$4)+D20*$E$46^($M$4))^(1/$M$4) -> 1.0487647 | O20: =$E$57+3*D20*$E$57*(($E$46-$E$57)/($E$46+2*$E$57-D20*($E$46-$E$57))) -> 1.0244689 | U20: =$Y$4 -> 0 | V20: =$E$46*(1-D20*(1+$Y$4))+$E$57*(2+D20*(1+$Y$4)) -> 22.521517 | W20: =-($E$46-$E$57)*D20*3*$E$57 -> -0.53896495 | X20: =IF(U20=0,-W20/V20,(-V20+SQRT(V20^2-4*U20*W20))/2*U20) -> 0.023931112 | Y20: =X20+$E$57 -> 1.0244689 | AA20: =E20^2*$AB$48+2*E20*D20*$AB$50+D20^2*$AB$49 -> -8.0147948e-06 | AB20: =$E$40/(($E$60*$E$43)*(1+(AA21*$E$40/($E$60*$E$43)))) -> 40.887607 | AC20: =$E$56*E20+$E$47*D20 -> 197.87345 | AD20: =(2*(AB20)*AC20*0.000001+1)/(1-(AB20)*AC20*0.000001) -> 1.0244697 | AF20: =$E$56*E20+$E$47*D20 -> 197.87345 | AG20: =(2*($E$40/($E$60*$E$43))*AF20*0.000001+1)/(1-($E$40/($E$60*$E$43))*AF20*0.000001) -> 1.0244615
... A36: 100 | C36: =1000000*(A36/100)*$E$45/$E$41 -> 303829.64 | D36: =C36/1000000 -> 0.30382964 | E36: =1-D36 -> 0.69617036 | G36: =E36*$E$57+D36*$E$46 -> 6.9858184 | I36: =(E36*$E$57^(1/2)+D36*$E$46^(1/2))^2 -> 4.3209893 | K36: =(E36*$E$57^(1/3)+D36*$E$46^(1/3))^3 -> 3.5852813 | M36: =(E36*$E$57^($M$4)+D36*$E$46^($M$4))^(1/$M$4) -> 3.5718626 | O36: =$E$57+3*D36*$E$57*(($E$46-$E$57)/($E$46+2*$E$57-D36*($E$46-$E$57))) -> 2.0752996 | U36: =$Y$4 -> 0 | V36: =$E$46*(1-D36*(1+$Y$4))+$E$57*(2+D36*(1+$Y$4)) -> 16.715795 | W36: =-($E$46-$E$57)*D36*3*$E$57 -> -17.965498 | X36: =IF(U36=0,-W36/V36,(-V36+SQRT(V36^2-4*U36*W36))/2*U36) -> 1.0747618 | Y36: =X36+$E$57 -> 2.0752996 | AA36: =E36^2*$AB$48+2*E36*D36*$AB$50+D36^2*$AB$49 -> -1.6077269e-05 | AB36: =$E$40/(($E$60*$E$43)*(1+(AA37*$E$40/($E$60*$E$43)))) -> 40.873998 | AC36: =$E$56*E36+$E$47*D36 -> 6453.9985 | AD36: =(2*(AB36)*AC36*0.000001+1)/(1-(AB36)*AC36*0.000001) -> 2.0749836 | AF36: =$E$56*E36+$E$47*D36 -> 6453.9985 | AG36: =(2*($E$40/($E$60*$E$43))*AF36*0.000001+1)/(1-($E$40/($E$60*$E$43))*AF36*0.000001) -> 2.0749836
A39: Environment Constants | AA39: AW | AB39: 3.96 | AF39: 3.96
A40: Ambient Pressure (P) [Pa] | E40: 101325 | AA40: BW | AB40: 20770 | AF40: 20770
A41: Ambient Pressure (P) [atm] | E41: =E40/101325 -> 1 | AA41: Πw | AB41: =AB39+AB40/E43 -> 73.622921 | AC41: =3.84+2.092*10000/E43 -> 74.006024 | AF41: 73.622921
A42: Temperature (T) [°C] | E42: 25
A43: Temperature (T) [K] | E43: =E42+273.15 -> 298.15 | M43: =1000/E43 -> 3.3540164
A45: Acetone Vapor Pressure [atm] | E45: =0.133322*10^($AF$46-$AG$46/(E42+$AH$46))/101.325 -> 0.30382964 | AF45: A | AG45: B | AH45: C
A46: Water Permittivity [NA] | E46: 20.7 | AF46: 7.11714 | AG46: 1210.595 | AH46: 229.664
A47: Acetone Molar Polarizability [cm³/mol] | E47: =(($E$46-1)/($E$46+2))*(($E$60*$E$43/$E$40)*1000000) -> 21232.114
AA48: BAA | AB48: =(34.9568-6687.72/(E43)-2101410/(E43^2)+92474600/(E43^3))*0.000001 -> -7.6244426e-06
A49: N2 Molecular Polarizability [Ǻ³] | E49: =(1.7037*1E-30+3.01*1E-34*E43-2*1E-37*E43^2)*1E+30 -> 1.7756645 | AA49: BWW | AB49: =E60*E43*(0.000000007-0.00000000147184*EXP(1734.29/E43))*0.000001 -> -1.2082519e-09
A50: O2 Molecular Polarizability [Ǻ³] | E50: =(1.5343*1E-30+2.88*1E-34*E43-1.63*1E-37*E43^2)*1E+30 -> 1.6056776 | AA50: BAW | AB50: =(32.366097-14113.8/(E43)-1244535/(E43^2)-2348789000/(E43^4))*0.000001 -> -2.9269363e-05
A51: Ar Molecular Polarizability [Ǻ³] | E51: =(1.62526*1E-30+1.649*1E-34*E43)*1E+30 -> 1.6744249
A52: N2 Fraction [%] | E52: 0.780818
A53: O2 Fraction [%] | E53: 0.209435
